{
  "nbformat": 4,
  "nbformat_minor": 0,
  "metadata": {
    "colab": {
      "name": "Chapter12_Tensorflow-TrainedModelConvert.ipynb",
      "provenance": [],
      "collapsed_sections": [],
      "toc_visible": true
    },
    "kernelspec": {
      "name": "python3",
      "display_name": "Python 3"
    },
    "accelerator": "GPU"
  },
  "cells": [
    {
      "cell_type": "markdown",
      "metadata": {
        "id": "yhzxsJb3dpWq",
        "colab_type": "text"
      },
      "source": [
        "# **TensorFlow Object Detection Model Conversion to Frozen Graph & TensorFlow Lite **\n",
        "\n"
      ]
    },
    {
      "cell_type": "code",
      "metadata": {
        "colab_type": "code",
        "outputId": "dc779dc6-5918-4759-ccb9-50dfd9a19a0d",
        "id": "Z5dd4JIAOPTF",
        "colab": {
          "base_uri": "https://localhost:8080/",
          "height": 34
        }
      },
      "source": [
        "%tensorflow_version 2.x\n",
        "!pip uninstall -y tensorflow"
      ],
      "execution_count": 1,
      "outputs": [
        {
          "output_type": "stream",
          "text": [
            "\u001b[33mWARNING: Skipping tensorflow as it is not installed.\u001b[0m\n"
          ],
          "name": "stdout"
        }
      ]
    },
    {
      "cell_type": "code",
      "metadata": {
        "id": "KLvZqWnnxeVi",
        "colab_type": "code",
        "outputId": "992139f3-368d-437b-ccf4-2174a2465e20",
        "colab": {
          "base_uri": "https://localhost:8080/",
          "height": 34
        }
      },
      "source": [
        "!pip install -U numpy==1.16.4."
      ],
      "execution_count": 2,
      "outputs": [
        {
          "output_type": "stream",
          "text": [
            "Requirement already up-to-date: numpy==1.16.4. in /usr/local/lib/python3.6/dist-packages (1.16.4)\n"
          ],
          "name": "stdout"
        }
      ]
    },
    {
      "cell_type": "code",
      "metadata": {
        "id": "MRo1bq7pOKAq",
        "colab_type": "code",
        "outputId": "225e10fc-3214-4273-ca92-9e2457abbb59",
        "colab": {
          "base_uri": "https://localhost:8080/",
          "height": 645
        }
      },
      "source": [
        "!pip install tensorflow-gpu==1.14.0\n",
        "import tensorflow as tf\n",
        "print(tf.__version__)"
      ],
      "execution_count": 3,
      "outputs": [
        {
          "output_type": "stream",
          "text": [
            "Collecting tensorflow-gpu==1.14.0\n",
            "\u001b[?25l  Downloading https://files.pythonhosted.org/packages/76/04/43153bfdfcf6c9a4c38ecdb971ca9a75b9a791bb69a764d652c359aca504/tensorflow_gpu-1.14.0-cp36-cp36m-manylinux1_x86_64.whl (377.0MB)\n",
            "\u001b[K     |████████████████████████████████| 377.0MB 44kB/s \n",
            "\u001b[?25hRequirement already satisfied: keras-preprocessing>=1.0.5 in /usr/local/lib/python3.6/dist-packages (from tensorflow-gpu==1.14.0) (1.1.0)\n",
            "Requirement already satisfied: protobuf>=3.6.1 in /usr/local/lib/python3.6/dist-packages (from tensorflow-gpu==1.14.0) (3.10.0)\n",
            "Requirement already satisfied: six>=1.10.0 in /usr/local/lib/python3.6/dist-packages (from tensorflow-gpu==1.14.0) (1.12.0)\n",
            "Collecting tensorflow-estimator<1.15.0rc0,>=1.14.0rc0\n",
            "\u001b[?25l  Downloading https://files.pythonhosted.org/packages/3c/d5/21860a5b11caf0678fbc8319341b0ae21a07156911132e0e71bffed0510d/tensorflow_estimator-1.14.0-py2.py3-none-any.whl (488kB)\n",
            "\u001b[K     |████████████████████████████████| 491kB 35.7MB/s \n",
            "\u001b[?25hRequirement already satisfied: google-pasta>=0.1.6 in /usr/local/lib/python3.6/dist-packages (from tensorflow-gpu==1.14.0) (0.2.0)\n",
            "Collecting tensorboard<1.15.0,>=1.14.0\n",
            "\u001b[?25l  Downloading https://files.pythonhosted.org/packages/91/2d/2ed263449a078cd9c8a9ba50ebd50123adf1f8cfbea1492f9084169b89d9/tensorboard-1.14.0-py3-none-any.whl (3.1MB)\n",
            "\u001b[K     |████████████████████████████████| 3.2MB 38.1MB/s \n",
            "\u001b[?25hRequirement already satisfied: numpy<2.0,>=1.14.5 in /usr/local/lib/python3.6/dist-packages (from tensorflow-gpu==1.14.0) (1.16.4)\n",
            "Requirement already satisfied: termcolor>=1.1.0 in /usr/local/lib/python3.6/dist-packages (from tensorflow-gpu==1.14.0) (1.1.0)\n",
            "Requirement already satisfied: gast>=0.2.0 in /usr/local/lib/python3.6/dist-packages (from tensorflow-gpu==1.14.0) (0.3.3)\n",
            "Requirement already satisfied: grpcio>=1.8.6 in /usr/local/lib/python3.6/dist-packages (from tensorflow-gpu==1.14.0) (1.28.1)\n",
            "Requirement already satisfied: wheel>=0.26 in /usr/local/lib/python3.6/dist-packages (from tensorflow-gpu==1.14.0) (0.34.2)\n",
            "Requirement already satisfied: astor>=0.6.0 in /usr/local/lib/python3.6/dist-packages (from tensorflow-gpu==1.14.0) (0.8.1)\n",
            "Requirement already satisfied: absl-py>=0.7.0 in /usr/local/lib/python3.6/dist-packages (from tensorflow-gpu==1.14.0) (0.9.0)\n",
            "Requirement already satisfied: wrapt>=1.11.1 in /usr/local/lib/python3.6/dist-packages (from tensorflow-gpu==1.14.0) (1.12.1)\n",
            "Requirement already satisfied: keras-applications>=1.0.6 in /usr/local/lib/python3.6/dist-packages (from tensorflow-gpu==1.14.0) (1.0.8)\n",
            "Requirement already satisfied: setuptools in /usr/local/lib/python3.6/dist-packages (from protobuf>=3.6.1->tensorflow-gpu==1.14.0) (46.1.3)\n",
            "Requirement already satisfied: werkzeug>=0.11.15 in /usr/local/lib/python3.6/dist-packages (from tensorboard<1.15.0,>=1.14.0->tensorflow-gpu==1.14.0) (1.0.1)\n",
            "Requirement already satisfied: markdown>=2.6.8 in /usr/local/lib/python3.6/dist-packages (from tensorboard<1.15.0,>=1.14.0->tensorflow-gpu==1.14.0) (3.2.1)\n",
            "Requirement already satisfied: h5py in /usr/local/lib/python3.6/dist-packages (from keras-applications>=1.0.6->tensorflow-gpu==1.14.0) (2.10.0)\n",
            "Installing collected packages: tensorflow-estimator, tensorboard, tensorflow-gpu\n",
            "  Found existing installation: tensorflow-estimator 2.2.0\n",
            "    Uninstalling tensorflow-estimator-2.2.0:\n",
            "      Successfully uninstalled tensorflow-estimator-2.2.0\n",
            "  Found existing installation: tensorboard 2.2.1\n",
            "    Uninstalling tensorboard-2.2.1:\n",
            "      Successfully uninstalled tensorboard-2.2.1\n",
            "Successfully installed tensorboard-1.14.0 tensorflow-estimator-1.14.0 tensorflow-gpu-1.14.0\n",
            "1.14.0\n"
          ],
          "name": "stdout"
        }
      ]
    },
    {
      "cell_type": "code",
      "metadata": {
        "id": "ecpHEnka8Kix",
        "colab_type": "code",
        "outputId": "c1be61cb-db71-4e7f-f70a-6b65b7551afa",
        "colab": {
          "base_uri": "https://localhost:8080/",
          "height": 729
        }
      },
      "source": [
        "%cd /content\n",
        "!git clone --quiet https://github.com/tensorflow/models.git\n",
        "\n",
        "!apt-get install -qq protobuf-compiler python-pil python-lxml python-tk\n",
        "\n",
        "!pip install -q Cython contextlib2 pillow lxml matplotlib\n",
        "\n",
        "!pip install -q pycocotools\n",
        "\n",
        "%cd /content/models/research\n",
        "!protoc object_detection/protos/*.proto --python_out=.\n",
        "\n",
        "import os\n",
        "os.environ['PYTHONPATH'] += ':/content/models/research/:/content/models/research/slim/'\n",
        "\n",
        "!python object_detection/builders/model_builder_test.py"
      ],
      "execution_count": 4,
      "outputs": [
        {
          "output_type": "stream",
          "text": [
            "/content\n",
            "Selecting previously unselected package python-bs4.\n",
            "(Reading database ... 144429 files and directories currently installed.)\n",
            "Preparing to unpack .../0-python-bs4_4.6.0-1_all.deb ...\n",
            "Unpacking python-bs4 (4.6.0-1) ...\n",
            "Selecting previously unselected package python-pkg-resources.\n",
            "Preparing to unpack .../1-python-pkg-resources_39.0.1-2_all.deb ...\n",
            "Unpacking python-pkg-resources (39.0.1-2) ...\n",
            "Selecting previously unselected package python-chardet.\n",
            "Preparing to unpack .../2-python-chardet_3.0.4-1_all.deb ...\n",
            "Unpacking python-chardet (3.0.4-1) ...\n",
            "Selecting previously unselected package python-six.\n",
            "Preparing to unpack .../3-python-six_1.11.0-2_all.deb ...\n",
            "Unpacking python-six (1.11.0-2) ...\n",
            "Selecting previously unselected package python-webencodings.\n",
            "Preparing to unpack .../4-python-webencodings_0.5-2_all.deb ...\n",
            "Unpacking python-webencodings (0.5-2) ...\n",
            "Selecting previously unselected package python-html5lib.\n",
            "Preparing to unpack .../5-python-html5lib_0.999999999-1_all.deb ...\n",
            "Unpacking python-html5lib (0.999999999-1) ...\n",
            "Selecting previously unselected package python-lxml:amd64.\n",
            "Preparing to unpack .../6-python-lxml_4.2.1-1ubuntu0.1_amd64.deb ...\n",
            "Unpacking python-lxml:amd64 (4.2.1-1ubuntu0.1) ...\n",
            "Selecting previously unselected package python-olefile.\n",
            "Preparing to unpack .../7-python-olefile_0.45.1-1_all.deb ...\n",
            "Unpacking python-olefile (0.45.1-1) ...\n",
            "Selecting previously unselected package python-pil:amd64.\n",
            "Preparing to unpack .../8-python-pil_5.1.0-1ubuntu0.2_amd64.deb ...\n",
            "Unpacking python-pil:amd64 (5.1.0-1ubuntu0.2) ...\n",
            "Setting up python-pkg-resources (39.0.1-2) ...\n",
            "Setting up python-six (1.11.0-2) ...\n",
            "Setting up python-bs4 (4.6.0-1) ...\n",
            "Setting up python-lxml:amd64 (4.2.1-1ubuntu0.1) ...\n",
            "Setting up python-olefile (0.45.1-1) ...\n",
            "Setting up python-pil:amd64 (5.1.0-1ubuntu0.2) ...\n",
            "Setting up python-webencodings (0.5-2) ...\n",
            "Setting up python-chardet (3.0.4-1) ...\n",
            "Setting up python-html5lib (0.999999999-1) ...\n",
            "Processing triggers for man-db (2.8.3-2ubuntu0.1) ...\n",
            "/content/models/research\n",
            "object_detection/protos/input_reader.proto: warning: Import object_detection/protos/image_resizer.proto but not used.\n"
          ],
          "name": "stdout"
        }
      ]
    },
    {
      "cell_type": "code",
      "metadata": {
        "id": "pBYS7m4y7aG1",
        "colab_type": "code",
        "colab": {}
      },
      "source": [
        "CONFIG_FILE = '/content/sample_data/train_pipeline.config'\n",
        "CHECKPOINT_PATH = '/content/sample_data/train_model.ckpt-2000'\n",
        "OUTPUT_DIR = '/content/sample_data'"
      ],
      "execution_count": 0,
      "outputs": []
    },
    {
      "cell_type": "code",
      "metadata": {
        "id": "UaBidS4nEGow",
        "colab_type": "code",
        "outputId": "aaa93240-405a-4ec2-d2b5-8a051ecc6abf",
        "colab": {
          "base_uri": "https://localhost:8080/",
          "height": 1000
        }
      },
      "source": [
        "import re\n",
        "import numpy as np\n",
        "\n",
        "\n",
        "!python /content/models/research/object_detection/export_tflite_ssd_graph.py \\\n",
        "    --input_type=image_tensor \\\n",
        "    --pipeline_config_path={CONFIG_FILE} \\\n",
        "    --output_directory={OUTPUT_DIR} \\\n",
        "    --trained_checkpoint_prefix={CHECKPOINT_PATH} \\\n",
        "    --add_postprocessing_op=true"
      ],
      "execution_count": 6,
      "outputs": [
        {
          "output_type": "stream",
          "text": [
            "WARNING:tensorflow:From /content/models/research/object_detection/export_tflite_ssd_graph.py:144: The name tf.app.run is deprecated. Please use tf.compat.v1.app.run instead.\n",
            "\n",
            "WARNING:tensorflow:From /content/models/research/object_detection/export_tflite_ssd_graph.py:134: The name tf.gfile.GFile is deprecated. Please use tf.io.gfile.GFile instead.\n",
            "\n",
            "W0513 14:31:11.006319 140206359324544 deprecation_wrapper.py:119] From /content/models/research/object_detection/export_tflite_ssd_graph.py:134: The name tf.gfile.GFile is deprecated. Please use tf.io.gfile.GFile instead.\n",
            "\n",
            "WARNING:tensorflow:From /content/models/research/object_detection/export_tflite_ssd_graph_lib.py:194: The name tf.gfile.MakeDirs is deprecated. Please use tf.io.gfile.makedirs instead.\n",
            "\n",
            "W0513 14:31:11.010630 140206359324544 deprecation_wrapper.py:119] From /content/models/research/object_detection/export_tflite_ssd_graph_lib.py:194: The name tf.gfile.MakeDirs is deprecated. Please use tf.io.gfile.makedirs instead.\n",
            "\n",
            "WARNING:tensorflow:From /content/models/research/object_detection/export_tflite_ssd_graph_lib.py:238: The name tf.placeholder is deprecated. Please use tf.compat.v1.placeholder instead.\n",
            "\n",
            "W0513 14:31:11.010960 140206359324544 deprecation_wrapper.py:119] From /content/models/research/object_detection/export_tflite_ssd_graph_lib.py:238: The name tf.placeholder is deprecated. Please use tf.compat.v1.placeholder instead.\n",
            "\n",
            "WARNING:tensorflow:From /content/models/research/object_detection/meta_architectures/ssd_meta_arch.py:608: The name tf.variable_scope is deprecated. Please use tf.compat.v1.variable_scope instead.\n",
            "\n",
            "W0513 14:31:11.014496 140206359324544 deprecation_wrapper.py:119] From /content/models/research/object_detection/meta_architectures/ssd_meta_arch.py:608: The name tf.variable_scope is deprecated. Please use tf.compat.v1.variable_scope instead.\n",
            "\n",
            "WARNING:tensorflow:Entity <bound method Conv.call of <tensorflow.python.layers.convolutional.Conv2D object at 0x7f840e3ee240>> could not be transformed and will be executed as-is. Please report this to the AutgoGraph team. When filing the bug, set the verbosity to 10 (on Linux, `export AUTOGRAPH_VERBOSITY=10`) and attach the full output. Cause: converting <bound method Conv.call of <tensorflow.python.layers.convolutional.Conv2D object at 0x7f840e3ee240>>: AssertionError: Bad argument number for Name: 3, expecting 4\n",
            "W0513 14:31:11.095544 140206359324544 ag_logging.py:145] Entity <bound method Conv.call of <tensorflow.python.layers.convolutional.Conv2D object at 0x7f840e3ee240>> could not be transformed and will be executed as-is. Please report this to the AutgoGraph team. When filing the bug, set the verbosity to 10 (on Linux, `export AUTOGRAPH_VERBOSITY=10`) and attach the full output. Cause: converting <bound method Conv.call of <tensorflow.python.layers.convolutional.Conv2D object at 0x7f840e3ee240>>: AssertionError: Bad argument number for Name: 3, expecting 4\n",
            "WARNING:tensorflow:Entity <bound method BatchNormalization.call of <tensorflow.python.layers.normalization.BatchNormalization object at 0x7f83e2b37898>> could not be transformed and will be executed as-is. Please report this to the AutgoGraph team. When filing the bug, set the verbosity to 10 (on Linux, `export AUTOGRAPH_VERBOSITY=10`) and attach the full output. Cause: converting <bound method BatchNormalization.call of <tensorflow.python.layers.normalization.BatchNormalization object at 0x7f83e2b37898>>: AssertionError: Bad argument number for Name: 3, expecting 4\n",
            "W0513 14:31:11.132556 140206359324544 ag_logging.py:145] Entity <bound method BatchNormalization.call of <tensorflow.python.layers.normalization.BatchNormalization object at 0x7f83e2b37898>> could not be transformed and will be executed as-is. Please report this to the AutgoGraph team. When filing the bug, set the verbosity to 10 (on Linux, `export AUTOGRAPH_VERBOSITY=10`) and attach the full output. Cause: converting <bound method BatchNormalization.call of <tensorflow.python.layers.normalization.BatchNormalization object at 0x7f83e2b37898>>: AssertionError: Bad argument number for Name: 3, expecting 4\n",
            "WARNING:tensorflow:Entity <bound method BatchNormalization.call of <tensorflow.python.layers.normalization.BatchNormalization object at 0x7f83e2b375f8>> could not be transformed and will be executed as-is. Please report this to the AutgoGraph team. When filing the bug, set the verbosity to 10 (on Linux, `export AUTOGRAPH_VERBOSITY=10`) and attach the full output. Cause: converting <bound method BatchNormalization.call of <tensorflow.python.layers.normalization.BatchNormalization object at 0x7f83e2b375f8>>: AssertionError: Bad argument number for Name: 3, expecting 4\n",
            "W0513 14:31:11.189683 140206359324544 ag_logging.py:145] Entity <bound method BatchNormalization.call of <tensorflow.python.layers.normalization.BatchNormalization object at 0x7f83e2b375f8>> could not be transformed and will be executed as-is. Please report this to the AutgoGraph team. When filing the bug, set the verbosity to 10 (on Linux, `export AUTOGRAPH_VERBOSITY=10`) and attach the full output. Cause: converting <bound method BatchNormalization.call of <tensorflow.python.layers.normalization.BatchNormalization object at 0x7f83e2b375f8>>: AssertionError: Bad argument number for Name: 3, expecting 4\n",
            "WARNING:tensorflow:Entity <bound method Conv.call of <tensorflow.python.layers.convolutional.Conv2D object at 0x7f83e2b11128>> could not be transformed and will be executed as-is. Please report this to the AutgoGraph team. When filing the bug, set the verbosity to 10 (on Linux, `export AUTOGRAPH_VERBOSITY=10`) and attach the full output. Cause: converting <bound method Conv.call of <tensorflow.python.layers.convolutional.Conv2D object at 0x7f83e2b11128>>: AssertionError: Bad argument number for Name: 3, expecting 4\n",
            "W0513 14:31:11.276289 140206359324544 ag_logging.py:145] Entity <bound method Conv.call of <tensorflow.python.layers.convolutional.Conv2D object at 0x7f83e2b11128>> could not be transformed and will be executed as-is. Please report this to the AutgoGraph team. When filing the bug, set the verbosity to 10 (on Linux, `export AUTOGRAPH_VERBOSITY=10`) and attach the full output. Cause: converting <bound method Conv.call of <tensorflow.python.layers.convolutional.Conv2D object at 0x7f83e2b11128>>: AssertionError: Bad argument number for Name: 3, expecting 4\n",
            "WARNING:tensorflow:Entity <bound method BatchNormalization.call of <tensorflow.python.layers.normalization.BatchNormalization object at 0x7f83e2aa6860>> could not be transformed and will be executed as-is. Please report this to the AutgoGraph team. When filing the bug, set the verbosity to 10 (on Linux, `export AUTOGRAPH_VERBOSITY=10`) and attach the full output. Cause: converting <bound method BatchNormalization.call of <tensorflow.python.layers.normalization.BatchNormalization object at 0x7f83e2aa6860>>: AssertionError: Bad argument number for Name: 3, expecting 4\n",
            "W0513 14:31:11.314085 140206359324544 ag_logging.py:145] Entity <bound method BatchNormalization.call of <tensorflow.python.layers.normalization.BatchNormalization object at 0x7f83e2aa6860>> could not be transformed and will be executed as-is. Please report this to the AutgoGraph team. When filing the bug, set the verbosity to 10 (on Linux, `export AUTOGRAPH_VERBOSITY=10`) and attach the full output. Cause: converting <bound method BatchNormalization.call of <tensorflow.python.layers.normalization.BatchNormalization object at 0x7f83e2aa6860>>: AssertionError: Bad argument number for Name: 3, expecting 4\n",
            "WARNING:tensorflow:Entity <bound method BatchNormalization.call of <tensorflow.python.layers.normalization.BatchNormalization object at 0x7f83e2b37c50>> could not be transformed and will be executed as-is. Please report this to the AutgoGraph team. When filing the bug, set the verbosity to 10 (on Linux, `export AUTOGRAPH_VERBOSITY=10`) and attach the full output. Cause: converting <bound method BatchNormalization.call of <tensorflow.python.layers.normalization.BatchNormalization object at 0x7f83e2b37c50>>: AssertionError: Bad argument number for Name: 3, expecting 4\n",
            "W0513 14:31:11.366871 140206359324544 ag_logging.py:145] Entity <bound method BatchNormalization.call of <tensorflow.python.layers.normalization.BatchNormalization object at 0x7f83e2b37c50>> could not be transformed and will be executed as-is. Please report this to the AutgoGraph team. When filing the bug, set the verbosity to 10 (on Linux, `export AUTOGRAPH_VERBOSITY=10`) and attach the full output. Cause: converting <bound method BatchNormalization.call of <tensorflow.python.layers.normalization.BatchNormalization object at 0x7f83e2b37c50>>: AssertionError: Bad argument number for Name: 3, expecting 4\n",
            "WARNING:tensorflow:Entity <bound method Conv.call of <tensorflow.python.layers.convolutional.Conv2D object at 0x7f83e2b37c50>> could not be transformed and will be executed as-is. Please report this to the AutgoGraph team. When filing the bug, set the verbosity to 10 (on Linux, `export AUTOGRAPH_VERBOSITY=10`) and attach the full output. Cause: converting <bound method Conv.call of <tensorflow.python.layers.convolutional.Conv2D object at 0x7f83e2b37c50>>: AssertionError: Bad argument number for Name: 3, expecting 4\n",
            "W0513 14:31:11.445933 140206359324544 ag_logging.py:145] Entity <bound method Conv.call of <tensorflow.python.layers.convolutional.Conv2D object at 0x7f83e2b37c50>> could not be transformed and will be executed as-is. Please report this to the AutgoGraph team. When filing the bug, set the verbosity to 10 (on Linux, `export AUTOGRAPH_VERBOSITY=10`) and attach the full output. Cause: converting <bound method Conv.call of <tensorflow.python.layers.convolutional.Conv2D object at 0x7f83e2b37c50>>: AssertionError: Bad argument number for Name: 3, expecting 4\n",
            "WARNING:tensorflow:Entity <bound method BatchNormalization.call of <tensorflow.python.layers.normalization.BatchNormalization object at 0x7f83e2b52630>> could not be transformed and will be executed as-is. Please report this to the AutgoGraph team. When filing the bug, set the verbosity to 10 (on Linux, `export AUTOGRAPH_VERBOSITY=10`) and attach the full output. Cause: converting <bound method BatchNormalization.call of <tensorflow.python.layers.normalization.BatchNormalization object at 0x7f83e2b52630>>: AssertionError: Bad argument number for Name: 3, expecting 4\n",
            "W0513 14:31:11.483947 140206359324544 ag_logging.py:145] Entity <bound method BatchNormalization.call of <tensorflow.python.layers.normalization.BatchNormalization object at 0x7f83e2b52630>> could not be transformed and will be executed as-is. Please report this to the AutgoGraph team. When filing the bug, set the verbosity to 10 (on Linux, `export AUTOGRAPH_VERBOSITY=10`) and attach the full output. Cause: converting <bound method BatchNormalization.call of <tensorflow.python.layers.normalization.BatchNormalization object at 0x7f83e2b52630>>: AssertionError: Bad argument number for Name: 3, expecting 4\n",
            "WARNING:tensorflow:Entity <bound method BatchNormalization.call of <tensorflow.python.layers.normalization.BatchNormalization object at 0x7f83e26a3978>> could not be transformed and will be executed as-is. Please report this to the AutgoGraph team. When filing the bug, set the verbosity to 10 (on Linux, `export AUTOGRAPH_VERBOSITY=10`) and attach the full output. Cause: converting <bound method BatchNormalization.call of <tensorflow.python.layers.normalization.BatchNormalization object at 0x7f83e26a3978>>: AssertionError: Bad argument number for Name: 3, expecting 4\n",
            "W0513 14:31:11.547213 140206359324544 ag_logging.py:145] Entity <bound method BatchNormalization.call of <tensorflow.python.layers.normalization.BatchNormalization object at 0x7f83e26a3978>> could not be transformed and will be executed as-is. Please report this to the AutgoGraph team. When filing the bug, set the verbosity to 10 (on Linux, `export AUTOGRAPH_VERBOSITY=10`) and attach the full output. Cause: converting <bound method BatchNormalization.call of <tensorflow.python.layers.normalization.BatchNormalization object at 0x7f83e26a3978>>: AssertionError: Bad argument number for Name: 3, expecting 4\n",
            "WARNING:tensorflow:Entity <bound method Conv.call of <tensorflow.python.layers.convolutional.Conv2D object at 0x7f83e26a3978>> could not be transformed and will be executed as-is. Please report this to the AutgoGraph team. When filing the bug, set the verbosity to 10 (on Linux, `export AUTOGRAPH_VERBOSITY=10`) and attach the full output. Cause: converting <bound method Conv.call of <tensorflow.python.layers.convolutional.Conv2D object at 0x7f83e26a3978>>: AssertionError: Bad argument number for Name: 3, expecting 4\n",
            "W0513 14:31:11.628531 140206359324544 ag_logging.py:145] Entity <bound method Conv.call of <tensorflow.python.layers.convolutional.Conv2D object at 0x7f83e26a3978>> could not be transformed and will be executed as-is. Please report this to the AutgoGraph team. When filing the bug, set the verbosity to 10 (on Linux, `export AUTOGRAPH_VERBOSITY=10`) and attach the full output. Cause: converting <bound method Conv.call of <tensorflow.python.layers.convolutional.Conv2D object at 0x7f83e26a3978>>: AssertionError: Bad argument number for Name: 3, expecting 4\n",
            "WARNING:tensorflow:Entity <bound method BatchNormalization.call of <tensorflow.python.layers.normalization.BatchNormalization object at 0x7f83e2bf7a90>> could not be transformed and will be executed as-is. Please report this to the AutgoGraph team. When filing the bug, set the verbosity to 10 (on Linux, `export AUTOGRAPH_VERBOSITY=10`) and attach the full output. Cause: converting <bound method BatchNormalization.call of <tensorflow.python.layers.normalization.BatchNormalization object at 0x7f83e2bf7a90>>: AssertionError: Bad argument number for Name: 3, expecting 4\n",
            "W0513 14:31:11.665806 140206359324544 ag_logging.py:145] Entity <bound method BatchNormalization.call of <tensorflow.python.layers.normalization.BatchNormalization object at 0x7f83e2bf7a90>> could not be transformed and will be executed as-is. Please report this to the AutgoGraph team. When filing the bug, set the verbosity to 10 (on Linux, `export AUTOGRAPH_VERBOSITY=10`) and attach the full output. Cause: converting <bound method BatchNormalization.call of <tensorflow.python.layers.normalization.BatchNormalization object at 0x7f83e2bf7a90>>: AssertionError: Bad argument number for Name: 3, expecting 4\n",
            "WARNING:tensorflow:Entity <bound method BatchNormalization.call of <tensorflow.python.layers.normalization.BatchNormalization object at 0x7f83e2bd44a8>> could not be transformed and will be executed as-is. Please report this to the AutgoGraph team. When filing the bug, set the verbosity to 10 (on Linux, `export AUTOGRAPH_VERBOSITY=10`) and attach the full output. Cause: converting <bound method BatchNormalization.call of <tensorflow.python.layers.normalization.BatchNormalization object at 0x7f83e2bd44a8>>: AssertionError: Bad argument number for Name: 3, expecting 4\n",
            "W0513 14:31:11.720482 140206359324544 ag_logging.py:145] Entity <bound method BatchNormalization.call of <tensorflow.python.layers.normalization.BatchNormalization object at 0x7f83e2bd44a8>> could not be transformed and will be executed as-is. Please report this to the AutgoGraph team. When filing the bug, set the verbosity to 10 (on Linux, `export AUTOGRAPH_VERBOSITY=10`) and attach the full output. Cause: converting <bound method BatchNormalization.call of <tensorflow.python.layers.normalization.BatchNormalization object at 0x7f83e2bd44a8>>: AssertionError: Bad argument number for Name: 3, expecting 4\n",
            "WARNING:tensorflow:Entity <bound method Conv.call of <tensorflow.python.layers.convolutional.Conv2D object at 0x7f83e2ba5da0>> could not be transformed and will be executed as-is. Please report this to the AutgoGraph team. When filing the bug, set the verbosity to 10 (on Linux, `export AUTOGRAPH_VERBOSITY=10`) and attach the full output. Cause: converting <bound method Conv.call of <tensorflow.python.layers.convolutional.Conv2D object at 0x7f83e2ba5da0>>: AssertionError: Bad argument number for Name: 3, expecting 4\n",
            "W0513 14:31:11.810095 140206359324544 ag_logging.py:145] Entity <bound method Conv.call of <tensorflow.python.layers.convolutional.Conv2D object at 0x7f83e2ba5da0>> could not be transformed and will be executed as-is. Please report this to the AutgoGraph team. When filing the bug, set the verbosity to 10 (on Linux, `export AUTOGRAPH_VERBOSITY=10`) and attach the full output. Cause: converting <bound method Conv.call of <tensorflow.python.layers.convolutional.Conv2D object at 0x7f83e2ba5da0>>: AssertionError: Bad argument number for Name: 3, expecting 4\n",
            "WARNING:tensorflow:Entity <bound method BatchNormalization.call of <tensorflow.python.layers.normalization.BatchNormalization object at 0x7f83e2a3e4a8>> could not be transformed and will be executed as-is. Please report this to the AutgoGraph team. When filing the bug, set the verbosity to 10 (on Linux, `export AUTOGRAPH_VERBOSITY=10`) and attach the full output. Cause: converting <bound method BatchNormalization.call of <tensorflow.python.layers.normalization.BatchNormalization object at 0x7f83e2a3e4a8>>: AssertionError: Bad argument number for Name: 3, expecting 4\n",
            "W0513 14:31:11.857468 140206359324544 ag_logging.py:145] Entity <bound method BatchNormalization.call of <tensorflow.python.layers.normalization.BatchNormalization object at 0x7f83e2a3e4a8>> could not be transformed and will be executed as-is. Please report this to the AutgoGraph team. When filing the bug, set the verbosity to 10 (on Linux, `export AUTOGRAPH_VERBOSITY=10`) and attach the full output. Cause: converting <bound method BatchNormalization.call of <tensorflow.python.layers.normalization.BatchNormalization object at 0x7f83e2a3e4a8>>: AssertionError: Bad argument number for Name: 3, expecting 4\n",
            "WARNING:tensorflow:Entity <bound method BatchNormalization.call of <tensorflow.python.layers.normalization.BatchNormalization object at 0x7f83e29eaf60>> could not be transformed and will be executed as-is. Please report this to the AutgoGraph team. When filing the bug, set the verbosity to 10 (on Linux, `export AUTOGRAPH_VERBOSITY=10`) and attach the full output. Cause: converting <bound method BatchNormalization.call of <tensorflow.python.layers.normalization.BatchNormalization object at 0x7f83e29eaf60>>: AssertionError: Bad argument number for Name: 3, expecting 4\n",
            "W0513 14:31:11.911953 140206359324544 ag_logging.py:145] Entity <bound method BatchNormalization.call of <tensorflow.python.layers.normalization.BatchNormalization object at 0x7f83e29eaf60>> could not be transformed and will be executed as-is. Please report this to the AutgoGraph team. When filing the bug, set the verbosity to 10 (on Linux, `export AUTOGRAPH_VERBOSITY=10`) and attach the full output. Cause: converting <bound method BatchNormalization.call of <tensorflow.python.layers.normalization.BatchNormalization object at 0x7f83e29eaf60>>: AssertionError: Bad argument number for Name: 3, expecting 4\n",
            "WARNING:tensorflow:Entity <bound method Conv.call of <tensorflow.python.layers.convolutional.Conv2D object at 0x7f83e2b972b0>> could not be transformed and will be executed as-is. Please report this to the AutgoGraph team. When filing the bug, set the verbosity to 10 (on Linux, `export AUTOGRAPH_VERBOSITY=10`) and attach the full output. Cause: converting <bound method Conv.call of <tensorflow.python.layers.convolutional.Conv2D object at 0x7f83e2b972b0>>: AssertionError: Bad argument number for Name: 3, expecting 4\n",
            "W0513 14:31:11.991506 140206359324544 ag_logging.py:145] Entity <bound method Conv.call of <tensorflow.python.layers.convolutional.Conv2D object at 0x7f83e2b972b0>> could not be transformed and will be executed as-is. Please report this to the AutgoGraph team. When filing the bug, set the verbosity to 10 (on Linux, `export AUTOGRAPH_VERBOSITY=10`) and attach the full output. Cause: converting <bound method Conv.call of <tensorflow.python.layers.convolutional.Conv2D object at 0x7f83e2b972b0>>: AssertionError: Bad argument number for Name: 3, expecting 4\n",
            "WARNING:tensorflow:Entity <bound method BatchNormalization.call of <tensorflow.python.layers.normalization.BatchNormalization object at 0x7f83e295fda0>> could not be transformed and will be executed as-is. Please report this to the AutgoGraph team. When filing the bug, set the verbosity to 10 (on Linux, `export AUTOGRAPH_VERBOSITY=10`) and attach the full output. Cause: converting <bound method BatchNormalization.call of <tensorflow.python.layers.normalization.BatchNormalization object at 0x7f83e295fda0>>: AssertionError: Bad argument number for Name: 3, expecting 4\n",
            "W0513 14:31:12.030015 140206359324544 ag_logging.py:145] Entity <bound method BatchNormalization.call of <tensorflow.python.layers.normalization.BatchNormalization object at 0x7f83e295fda0>> could not be transformed and will be executed as-is. Please report this to the AutgoGraph team. When filing the bug, set the verbosity to 10 (on Linux, `export AUTOGRAPH_VERBOSITY=10`) and attach the full output. Cause: converting <bound method BatchNormalization.call of <tensorflow.python.layers.normalization.BatchNormalization object at 0x7f83e295fda0>>: AssertionError: Bad argument number for Name: 3, expecting 4\n",
            "WARNING:tensorflow:Entity <bound method BatchNormalization.call of <tensorflow.python.layers.normalization.BatchNormalization object at 0x7f83e2931e48>> could not be transformed and will be executed as-is. Please report this to the AutgoGraph team. When filing the bug, set the verbosity to 10 (on Linux, `export AUTOGRAPH_VERBOSITY=10`) and attach the full output. Cause: converting <bound method BatchNormalization.call of <tensorflow.python.layers.normalization.BatchNormalization object at 0x7f83e2931e48>>: AssertionError: Bad argument number for Name: 3, expecting 4\n",
            "W0513 14:31:12.083268 140206359324544 ag_logging.py:145] Entity <bound method BatchNormalization.call of <tensorflow.python.layers.normalization.BatchNormalization object at 0x7f83e2931e48>> could not be transformed and will be executed as-is. Please report this to the AutgoGraph team. When filing the bug, set the verbosity to 10 (on Linux, `export AUTOGRAPH_VERBOSITY=10`) and attach the full output. Cause: converting <bound method BatchNormalization.call of <tensorflow.python.layers.normalization.BatchNormalization object at 0x7f83e2931e48>>: AssertionError: Bad argument number for Name: 3, expecting 4\n",
            "WARNING:tensorflow:Entity <bound method Conv.call of <tensorflow.python.layers.convolutional.Conv2D object at 0x7f83e2b52978>> could not be transformed and will be executed as-is. Please report this to the AutgoGraph team. When filing the bug, set the verbosity to 10 (on Linux, `export AUTOGRAPH_VERBOSITY=10`) and attach the full output. Cause: converting <bound method Conv.call of <tensorflow.python.layers.convolutional.Conv2D object at 0x7f83e2b52978>>: AssertionError: Bad argument number for Name: 3, expecting 4\n",
            "W0513 14:31:12.168468 140206359324544 ag_logging.py:145] Entity <bound method Conv.call of <tensorflow.python.layers.convolutional.Conv2D object at 0x7f83e2b52978>> could not be transformed and will be executed as-is. Please report this to the AutgoGraph team. When filing the bug, set the verbosity to 10 (on Linux, `export AUTOGRAPH_VERBOSITY=10`) and attach the full output. Cause: converting <bound method Conv.call of <tensorflow.python.layers.convolutional.Conv2D object at 0x7f83e2b52978>>: AssertionError: Bad argument number for Name: 3, expecting 4\n",
            "WARNING:tensorflow:Entity <bound method BatchNormalization.call of <tensorflow.python.layers.normalization.BatchNormalization object at 0x7f83e28f49e8>> could not be transformed and will be executed as-is. Please report this to the AutgoGraph team. When filing the bug, set the verbosity to 10 (on Linux, `export AUTOGRAPH_VERBOSITY=10`) and attach the full output. Cause: converting <bound method BatchNormalization.call of <tensorflow.python.layers.normalization.BatchNormalization object at 0x7f83e28f49e8>>: AssertionError: Bad argument number for Name: 3, expecting 4\n",
            "W0513 14:31:12.205682 140206359324544 ag_logging.py:145] Entity <bound method BatchNormalization.call of <tensorflow.python.layers.normalization.BatchNormalization object at 0x7f83e28f49e8>> could not be transformed and will be executed as-is. Please report this to the AutgoGraph team. When filing the bug, set the verbosity to 10 (on Linux, `export AUTOGRAPH_VERBOSITY=10`) and attach the full output. Cause: converting <bound method BatchNormalization.call of <tensorflow.python.layers.normalization.BatchNormalization object at 0x7f83e28f49e8>>: AssertionError: Bad argument number for Name: 3, expecting 4\n",
            "WARNING:tensorflow:Entity <bound method BatchNormalization.call of <tensorflow.python.layers.normalization.BatchNormalization object at 0x7f83e28aa320>> could not be transformed and will be executed as-is. Please report this to the AutgoGraph team. When filing the bug, set the verbosity to 10 (on Linux, `export AUTOGRAPH_VERBOSITY=10`) and attach the full output. Cause: converting <bound method BatchNormalization.call of <tensorflow.python.layers.normalization.BatchNormalization object at 0x7f83e28aa320>>: AssertionError: Bad argument number for Name: 3, expecting 4\n",
            "W0513 14:31:12.258926 140206359324544 ag_logging.py:145] Entity <bound method BatchNormalization.call of <tensorflow.python.layers.normalization.BatchNormalization object at 0x7f83e28aa320>> could not be transformed and will be executed as-is. Please report this to the AutgoGraph team. When filing the bug, set the verbosity to 10 (on Linux, `export AUTOGRAPH_VERBOSITY=10`) and attach the full output. Cause: converting <bound method BatchNormalization.call of <tensorflow.python.layers.normalization.BatchNormalization object at 0x7f83e28aa320>>: AssertionError: Bad argument number for Name: 3, expecting 4\n",
            "WARNING:tensorflow:Entity <bound method Conv.call of <tensorflow.python.layers.convolutional.Conv2D object at 0x7f83e28ebbe0>> could not be transformed and will be executed as-is. Please report this to the AutgoGraph team. When filing the bug, set the verbosity to 10 (on Linux, `export AUTOGRAPH_VERBOSITY=10`) and attach the full output. Cause: converting <bound method Conv.call of <tensorflow.python.layers.convolutional.Conv2D object at 0x7f83e28ebbe0>>: AssertionError: Bad argument number for Name: 3, expecting 4\n",
            "W0513 14:31:12.337284 140206359324544 ag_logging.py:145] Entity <bound method Conv.call of <tensorflow.python.layers.convolutional.Conv2D object at 0x7f83e28ebbe0>> could not be transformed and will be executed as-is. Please report this to the AutgoGraph team. When filing the bug, set the verbosity to 10 (on Linux, `export AUTOGRAPH_VERBOSITY=10`) and attach the full output. Cause: converting <bound method Conv.call of <tensorflow.python.layers.convolutional.Conv2D object at 0x7f83e28ebbe0>>: AssertionError: Bad argument number for Name: 3, expecting 4\n",
            "WARNING:tensorflow:Entity <bound method BatchNormalization.call of <tensorflow.python.layers.normalization.BatchNormalization object at 0x7f83e2aeaa20>> could not be transformed and will be executed as-is. Please report this to the AutgoGraph team. When filing the bug, set the verbosity to 10 (on Linux, `export AUTOGRAPH_VERBOSITY=10`) and attach the full output. Cause: converting <bound method BatchNormalization.call of <tensorflow.python.layers.normalization.BatchNormalization object at 0x7f83e2aeaa20>>: AssertionError: Bad argument number for Name: 3, expecting 4\n",
            "W0513 14:31:12.374539 140206359324544 ag_logging.py:145] Entity <bound method BatchNormalization.call of <tensorflow.python.layers.normalization.BatchNormalization object at 0x7f83e2aeaa20>> could not be transformed and will be executed as-is. Please report this to the AutgoGraph team. When filing the bug, set the verbosity to 10 (on Linux, `export AUTOGRAPH_VERBOSITY=10`) and attach the full output. Cause: converting <bound method BatchNormalization.call of <tensorflow.python.layers.normalization.BatchNormalization object at 0x7f83e2aeaa20>>: AssertionError: Bad argument number for Name: 3, expecting 4\n",
            "WARNING:tensorflow:Entity <bound method BatchNormalization.call of <tensorflow.python.layers.normalization.BatchNormalization object at 0x7f83e28807f0>> could not be transformed and will be executed as-is. Please report this to the AutgoGraph team. When filing the bug, set the verbosity to 10 (on Linux, `export AUTOGRAPH_VERBOSITY=10`) and attach the full output. Cause: converting <bound method BatchNormalization.call of <tensorflow.python.layers.normalization.BatchNormalization object at 0x7f83e28807f0>>: AssertionError: Bad argument number for Name: 3, expecting 4\n",
            "W0513 14:31:12.427667 140206359324544 ag_logging.py:145] Entity <bound method BatchNormalization.call of <tensorflow.python.layers.normalization.BatchNormalization object at 0x7f83e28807f0>> could not be transformed and will be executed as-is. Please report this to the AutgoGraph team. When filing the bug, set the verbosity to 10 (on Linux, `export AUTOGRAPH_VERBOSITY=10`) and attach the full output. Cause: converting <bound method BatchNormalization.call of <tensorflow.python.layers.normalization.BatchNormalization object at 0x7f83e28807f0>>: AssertionError: Bad argument number for Name: 3, expecting 4\n",
            "WARNING:tensorflow:Entity <bound method Conv.call of <tensorflow.python.layers.convolutional.Conv2D object at 0x7f83e2822748>> could not be transformed and will be executed as-is. Please report this to the AutgoGraph team. When filing the bug, set the verbosity to 10 (on Linux, `export AUTOGRAPH_VERBOSITY=10`) and attach the full output. Cause: converting <bound method Conv.call of <tensorflow.python.layers.convolutional.Conv2D object at 0x7f83e2822748>>: AssertionError: Bad argument number for Name: 3, expecting 4\n",
            "W0513 14:31:12.515298 140206359324544 ag_logging.py:145] Entity <bound method Conv.call of <tensorflow.python.layers.convolutional.Conv2D object at 0x7f83e2822748>> could not be transformed and will be executed as-is. Please report this to the AutgoGraph team. When filing the bug, set the verbosity to 10 (on Linux, `export AUTOGRAPH_VERBOSITY=10`) and attach the full output. Cause: converting <bound method Conv.call of <tensorflow.python.layers.convolutional.Conv2D object at 0x7f83e2822748>>: AssertionError: Bad argument number for Name: 3, expecting 4\n",
            "WARNING:tensorflow:Entity <bound method BatchNormalization.call of <tensorflow.python.layers.normalization.BatchNormalization object at 0x7f83e26a38d0>> could not be transformed and will be executed as-is. Please report this to the AutgoGraph team. When filing the bug, set the verbosity to 10 (on Linux, `export AUTOGRAPH_VERBOSITY=10`) and attach the full output. Cause: converting <bound method BatchNormalization.call of <tensorflow.python.layers.normalization.BatchNormalization object at 0x7f83e26a38d0>>: AssertionError: Bad argument number for Name: 3, expecting 4\n",
            "W0513 14:31:12.559994 140206359324544 ag_logging.py:145] Entity <bound method BatchNormalization.call of <tensorflow.python.layers.normalization.BatchNormalization object at 0x7f83e26a38d0>> could not be transformed and will be executed as-is. Please report this to the AutgoGraph team. When filing the bug, set the verbosity to 10 (on Linux, `export AUTOGRAPH_VERBOSITY=10`) and attach the full output. Cause: converting <bound method BatchNormalization.call of <tensorflow.python.layers.normalization.BatchNormalization object at 0x7f83e26a38d0>>: AssertionError: Bad argument number for Name: 3, expecting 4\n",
            "WARNING:tensorflow:Entity <bound method BatchNormalization.call of <tensorflow.python.layers.normalization.BatchNormalization object at 0x7f83e2778048>> could not be transformed and will be executed as-is. Please report this to the AutgoGraph team. When filing the bug, set the verbosity to 10 (on Linux, `export AUTOGRAPH_VERBOSITY=10`) and attach the full output. Cause: converting <bound method BatchNormalization.call of <tensorflow.python.layers.normalization.BatchNormalization object at 0x7f83e2778048>>: AssertionError: Bad argument number for Name: 3, expecting 4\n",
            "W0513 14:31:12.613255 140206359324544 ag_logging.py:145] Entity <bound method BatchNormalization.call of <tensorflow.python.layers.normalization.BatchNormalization object at 0x7f83e2778048>> could not be transformed and will be executed as-is. Please report this to the AutgoGraph team. When filing the bug, set the verbosity to 10 (on Linux, `export AUTOGRAPH_VERBOSITY=10`) and attach the full output. Cause: converting <bound method BatchNormalization.call of <tensorflow.python.layers.normalization.BatchNormalization object at 0x7f83e2778048>>: AssertionError: Bad argument number for Name: 3, expecting 4\n",
            "WARNING:tensorflow:Entity <bound method Conv.call of <tensorflow.python.layers.convolutional.Conv2D object at 0x7f83e2726b70>> could not be transformed and will be executed as-is. Please report this to the AutgoGraph team. When filing the bug, set the verbosity to 10 (on Linux, `export AUTOGRAPH_VERBOSITY=10`) and attach the full output. Cause: converting <bound method Conv.call of <tensorflow.python.layers.convolutional.Conv2D object at 0x7f83e2726b70>>: AssertionError: Bad argument number for Name: 3, expecting 4\n",
            "W0513 14:31:12.689588 140206359324544 ag_logging.py:145] Entity <bound method Conv.call of <tensorflow.python.layers.convolutional.Conv2D object at 0x7f83e2726b70>> could not be transformed and will be executed as-is. Please report this to the AutgoGraph team. When filing the bug, set the verbosity to 10 (on Linux, `export AUTOGRAPH_VERBOSITY=10`) and attach the full output. Cause: converting <bound method Conv.call of <tensorflow.python.layers.convolutional.Conv2D object at 0x7f83e2726b70>>: AssertionError: Bad argument number for Name: 3, expecting 4\n",
            "WARNING:tensorflow:Entity <bound method BatchNormalization.call of <tensorflow.python.layers.normalization.BatchNormalization object at 0x7f83e2bf7fd0>> could not be transformed and will be executed as-is. Please report this to the AutgoGraph team. When filing the bug, set the verbosity to 10 (on Linux, `export AUTOGRAPH_VERBOSITY=10`) and attach the full output. Cause: converting <bound method BatchNormalization.call of <tensorflow.python.layers.normalization.BatchNormalization object at 0x7f83e2bf7fd0>>: AssertionError: Bad argument number for Name: 3, expecting 4\n",
            "W0513 14:31:12.727114 140206359324544 ag_logging.py:145] Entity <bound method BatchNormalization.call of <tensorflow.python.layers.normalization.BatchNormalization object at 0x7f83e2bf7fd0>> could not be transformed and will be executed as-is. Please report this to the AutgoGraph team. When filing the bug, set the verbosity to 10 (on Linux, `export AUTOGRAPH_VERBOSITY=10`) and attach the full output. Cause: converting <bound method BatchNormalization.call of <tensorflow.python.layers.normalization.BatchNormalization object at 0x7f83e2bf7fd0>>: AssertionError: Bad argument number for Name: 3, expecting 4\n",
            "WARNING:tensorflow:Entity <bound method BatchNormalization.call of <tensorflow.python.layers.normalization.BatchNormalization object at 0x7f83e26de780>> could not be transformed and will be executed as-is. Please report this to the AutgoGraph team. When filing the bug, set the verbosity to 10 (on Linux, `export AUTOGRAPH_VERBOSITY=10`) and attach the full output. Cause: converting <bound method BatchNormalization.call of <tensorflow.python.layers.normalization.BatchNormalization object at 0x7f83e26de780>>: AssertionError: Bad argument number for Name: 3, expecting 4\n",
            "W0513 14:31:12.793030 140206359324544 ag_logging.py:145] Entity <bound method BatchNormalization.call of <tensorflow.python.layers.normalization.BatchNormalization object at 0x7f83e26de780>> could not be transformed and will be executed as-is. Please report this to the AutgoGraph team. When filing the bug, set the verbosity to 10 (on Linux, `export AUTOGRAPH_VERBOSITY=10`) and attach the full output. Cause: converting <bound method BatchNormalization.call of <tensorflow.python.layers.normalization.BatchNormalization object at 0x7f83e26de780>>: AssertionError: Bad argument number for Name: 3, expecting 4\n",
            "WARNING:tensorflow:Entity <bound method Conv.call of <tensorflow.python.layers.convolutional.Conv2D object at 0x7f83e1dcedd8>> could not be transformed and will be executed as-is. Please report this to the AutgoGraph team. When filing the bug, set the verbosity to 10 (on Linux, `export AUTOGRAPH_VERBOSITY=10`) and attach the full output. Cause: converting <bound method Conv.call of <tensorflow.python.layers.convolutional.Conv2D object at 0x7f83e1dcedd8>>: AssertionError: Bad argument number for Name: 3, expecting 4\n",
            "W0513 14:31:12.872455 140206359324544 ag_logging.py:145] Entity <bound method Conv.call of <tensorflow.python.layers.convolutional.Conv2D object at 0x7f83e1dcedd8>> could not be transformed and will be executed as-is. Please report this to the AutgoGraph team. When filing the bug, set the verbosity to 10 (on Linux, `export AUTOGRAPH_VERBOSITY=10`) and attach the full output. Cause: converting <bound method Conv.call of <tensorflow.python.layers.convolutional.Conv2D object at 0x7f83e1dcedd8>>: AssertionError: Bad argument number for Name: 3, expecting 4\n",
            "WARNING:tensorflow:Entity <bound method BatchNormalization.call of <tensorflow.python.layers.normalization.BatchNormalization object at 0x7f83e2a3e438>> could not be transformed and will be executed as-is. Please report this to the AutgoGraph team. When filing the bug, set the verbosity to 10 (on Linux, `export AUTOGRAPH_VERBOSITY=10`) and attach the full output. Cause: converting <bound method BatchNormalization.call of <tensorflow.python.layers.normalization.BatchNormalization object at 0x7f83e2a3e438>>: AssertionError: Bad argument number for Name: 3, expecting 4\n",
            "W0513 14:31:12.911229 140206359324544 ag_logging.py:145] Entity <bound method BatchNormalization.call of <tensorflow.python.layers.normalization.BatchNormalization object at 0x7f83e2a3e438>> could not be transformed and will be executed as-is. Please report this to the AutgoGraph team. When filing the bug, set the verbosity to 10 (on Linux, `export AUTOGRAPH_VERBOSITY=10`) and attach the full output. Cause: converting <bound method BatchNormalization.call of <tensorflow.python.layers.normalization.BatchNormalization object at 0x7f83e2a3e438>>: AssertionError: Bad argument number for Name: 3, expecting 4\n",
            "WARNING:tensorflow:Entity <bound method BatchNormalization.call of <tensorflow.python.layers.normalization.BatchNormalization object at 0x7f83e26debe0>> could not be transformed and will be executed as-is. Please report this to the AutgoGraph team. When filing the bug, set the verbosity to 10 (on Linux, `export AUTOGRAPH_VERBOSITY=10`) and attach the full output. Cause: converting <bound method BatchNormalization.call of <tensorflow.python.layers.normalization.BatchNormalization object at 0x7f83e26debe0>>: AssertionError: Bad argument number for Name: 3, expecting 4\n",
            "W0513 14:31:12.970701 140206359324544 ag_logging.py:145] Entity <bound method BatchNormalization.call of <tensorflow.python.layers.normalization.BatchNormalization object at 0x7f83e26debe0>> could not be transformed and will be executed as-is. Please report this to the AutgoGraph team. When filing the bug, set the verbosity to 10 (on Linux, `export AUTOGRAPH_VERBOSITY=10`) and attach the full output. Cause: converting <bound method BatchNormalization.call of <tensorflow.python.layers.normalization.BatchNormalization object at 0x7f83e26debe0>>: AssertionError: Bad argument number for Name: 3, expecting 4\n",
            "WARNING:tensorflow:Entity <bound method Conv.call of <tensorflow.python.layers.convolutional.Conv2D object at 0x7f83e26debe0>> could not be transformed and will be executed as-is. Please report this to the AutgoGraph team. When filing the bug, set the verbosity to 10 (on Linux, `export AUTOGRAPH_VERBOSITY=10`) and attach the full output. Cause: converting <bound method Conv.call of <tensorflow.python.layers.convolutional.Conv2D object at 0x7f83e26debe0>>: AssertionError: Bad argument number for Name: 3, expecting 4\n",
            "W0513 14:31:13.050900 140206359324544 ag_logging.py:145] Entity <bound method Conv.call of <tensorflow.python.layers.convolutional.Conv2D object at 0x7f83e26debe0>> could not be transformed and will be executed as-is. Please report this to the AutgoGraph team. When filing the bug, set the verbosity to 10 (on Linux, `export AUTOGRAPH_VERBOSITY=10`) and attach the full output. Cause: converting <bound method Conv.call of <tensorflow.python.layers.convolutional.Conv2D object at 0x7f83e26debe0>>: AssertionError: Bad argument number for Name: 3, expecting 4\n",
            "WARNING:tensorflow:Entity <bound method BatchNormalization.call of <tensorflow.python.layers.normalization.BatchNormalization object at 0x7f83e2952780>> could not be transformed and will be executed as-is. Please report this to the AutgoGraph team. When filing the bug, set the verbosity to 10 (on Linux, `export AUTOGRAPH_VERBOSITY=10`) and attach the full output. Cause: converting <bound method BatchNormalization.call of <tensorflow.python.layers.normalization.BatchNormalization object at 0x7f83e2952780>>: AssertionError: Bad argument number for Name: 3, expecting 4\n",
            "W0513 14:31:13.087077 140206359324544 ag_logging.py:145] Entity <bound method BatchNormalization.call of <tensorflow.python.layers.normalization.BatchNormalization object at 0x7f83e2952780>> could not be transformed and will be executed as-is. Please report this to the AutgoGraph team. When filing the bug, set the verbosity to 10 (on Linux, `export AUTOGRAPH_VERBOSITY=10`) and attach the full output. Cause: converting <bound method BatchNormalization.call of <tensorflow.python.layers.normalization.BatchNormalization object at 0x7f83e2952780>>: AssertionError: Bad argument number for Name: 3, expecting 4\n",
            "WARNING:tensorflow:Entity <bound method BatchNormalization.call of <tensorflow.python.layers.normalization.BatchNormalization object at 0x7f83e1cb5080>> could not be transformed and will be executed as-is. Please report this to the AutgoGraph team. When filing the bug, set the verbosity to 10 (on Linux, `export AUTOGRAPH_VERBOSITY=10`) and attach the full output. Cause: converting <bound method BatchNormalization.call of <tensorflow.python.layers.normalization.BatchNormalization object at 0x7f83e1cb5080>>: AssertionError: Bad argument number for Name: 3, expecting 4\n",
            "W0513 14:31:13.139345 140206359324544 ag_logging.py:145] Entity <bound method BatchNormalization.call of <tensorflow.python.layers.normalization.BatchNormalization object at 0x7f83e1cb5080>> could not be transformed and will be executed as-is. Please report this to the AutgoGraph team. When filing the bug, set the verbosity to 10 (on Linux, `export AUTOGRAPH_VERBOSITY=10`) and attach the full output. Cause: converting <bound method BatchNormalization.call of <tensorflow.python.layers.normalization.BatchNormalization object at 0x7f83e1cb5080>>: AssertionError: Bad argument number for Name: 3, expecting 4\n",
            "WARNING:tensorflow:Entity <bound method Conv.call of <tensorflow.python.layers.convolutional.Conv2D object at 0x7f83e1cf3240>> could not be transformed and will be executed as-is. Please report this to the AutgoGraph team. When filing the bug, set the verbosity to 10 (on Linux, `export AUTOGRAPH_VERBOSITY=10`) and attach the full output. Cause: converting <bound method Conv.call of <tensorflow.python.layers.convolutional.Conv2D object at 0x7f83e1cf3240>>: AssertionError: Bad argument number for Name: 3, expecting 4\n",
            "W0513 14:31:13.223169 140206359324544 ag_logging.py:145] Entity <bound method Conv.call of <tensorflow.python.layers.convolutional.Conv2D object at 0x7f83e1cf3240>> could not be transformed and will be executed as-is. Please report this to the AutgoGraph team. When filing the bug, set the verbosity to 10 (on Linux, `export AUTOGRAPH_VERBOSITY=10`) and attach the full output. Cause: converting <bound method Conv.call of <tensorflow.python.layers.convolutional.Conv2D object at 0x7f83e1cf3240>>: AssertionError: Bad argument number for Name: 3, expecting 4\n",
            "WARNING:tensorflow:Entity <bound method BatchNormalization.call of <tensorflow.python.layers.normalization.BatchNormalization object at 0x7f83e28eb2e8>> could not be transformed and will be executed as-is. Please report this to the AutgoGraph team. When filing the bug, set the verbosity to 10 (on Linux, `export AUTOGRAPH_VERBOSITY=10`) and attach the full output. Cause: converting <bound method BatchNormalization.call of <tensorflow.python.layers.normalization.BatchNormalization object at 0x7f83e28eb2e8>>: AssertionError: Bad argument number for Name: 3, expecting 4\n",
            "W0513 14:31:13.260760 140206359324544 ag_logging.py:145] Entity <bound method BatchNormalization.call of <tensorflow.python.layers.normalization.BatchNormalization object at 0x7f83e28eb2e8>> could not be transformed and will be executed as-is. Please report this to the AutgoGraph team. When filing the bug, set the verbosity to 10 (on Linux, `export AUTOGRAPH_VERBOSITY=10`) and attach the full output. Cause: converting <bound method BatchNormalization.call of <tensorflow.python.layers.normalization.BatchNormalization object at 0x7f83e28eb2e8>>: AssertionError: Bad argument number for Name: 3, expecting 4\n",
            "WARNING:tensorflow:Entity <bound method BatchNormalization.call of <tensorflow.python.layers.normalization.BatchNormalization object at 0x7f83e1cb5080>> could not be transformed and will be executed as-is. Please report this to the AutgoGraph team. When filing the bug, set the verbosity to 10 (on Linux, `export AUTOGRAPH_VERBOSITY=10`) and attach the full output. Cause: converting <bound method BatchNormalization.call of <tensorflow.python.layers.normalization.BatchNormalization object at 0x7f83e1cb5080>>: AssertionError: Bad argument number for Name: 3, expecting 4\n",
            "W0513 14:31:13.311495 140206359324544 ag_logging.py:145] Entity <bound method BatchNormalization.call of <tensorflow.python.layers.normalization.BatchNormalization object at 0x7f83e1cb5080>> could not be transformed and will be executed as-is. Please report this to the AutgoGraph team. When filing the bug, set the verbosity to 10 (on Linux, `export AUTOGRAPH_VERBOSITY=10`) and attach the full output. Cause: converting <bound method BatchNormalization.call of <tensorflow.python.layers.normalization.BatchNormalization object at 0x7f83e1cb5080>>: AssertionError: Bad argument number for Name: 3, expecting 4\n",
            "WARNING:tensorflow:Entity <bound method Conv.call of <tensorflow.python.layers.convolutional.Conv2D object at 0x7f83e1cb5080>> could not be transformed and will be executed as-is. Please report this to the AutgoGraph team. When filing the bug, set the verbosity to 10 (on Linux, `export AUTOGRAPH_VERBOSITY=10`) and attach the full output. Cause: converting <bound method Conv.call of <tensorflow.python.layers.convolutional.Conv2D object at 0x7f83e1cb5080>>: AssertionError: Bad argument number for Name: 3, expecting 4\n",
            "W0513 14:31:13.394714 140206359324544 ag_logging.py:145] Entity <bound method Conv.call of <tensorflow.python.layers.convolutional.Conv2D object at 0x7f83e1cb5080>> could not be transformed and will be executed as-is. Please report this to the AutgoGraph team. When filing the bug, set the verbosity to 10 (on Linux, `export AUTOGRAPH_VERBOSITY=10`) and attach the full output. Cause: converting <bound method Conv.call of <tensorflow.python.layers.convolutional.Conv2D object at 0x7f83e1cb5080>>: AssertionError: Bad argument number for Name: 3, expecting 4\n",
            "WARNING:tensorflow:Entity <bound method BatchNormalization.call of <tensorflow.python.layers.normalization.BatchNormalization object at 0x7f83e2880908>> could not be transformed and will be executed as-is. Please report this to the AutgoGraph team. When filing the bug, set the verbosity to 10 (on Linux, `export AUTOGRAPH_VERBOSITY=10`) and attach the full output. Cause: converting <bound method BatchNormalization.call of <tensorflow.python.layers.normalization.BatchNormalization object at 0x7f83e2880908>>: AssertionError: Bad argument number for Name: 3, expecting 4\n",
            "W0513 14:31:13.434726 140206359324544 ag_logging.py:145] Entity <bound method BatchNormalization.call of <tensorflow.python.layers.normalization.BatchNormalization object at 0x7f83e2880908>> could not be transformed and will be executed as-is. Please report this to the AutgoGraph team. When filing the bug, set the verbosity to 10 (on Linux, `export AUTOGRAPH_VERBOSITY=10`) and attach the full output. Cause: converting <bound method BatchNormalization.call of <tensorflow.python.layers.normalization.BatchNormalization object at 0x7f83e2880908>>: AssertionError: Bad argument number for Name: 3, expecting 4\n",
            "WARNING:tensorflow:Entity <bound method Conv.call of <tensorflow.python.layers.convolutional.Conv2D object at 0x7f83e26404e0>> could not be transformed and will be executed as-is. Please report this to the AutgoGraph team. When filing the bug, set the verbosity to 10 (on Linux, `export AUTOGRAPH_VERBOSITY=10`) and attach the full output. Cause: converting <bound method Conv.call of <tensorflow.python.layers.convolutional.Conv2D object at 0x7f83e26404e0>>: AssertionError: Bad argument number for Name: 3, expecting 4\n",
            "W0513 14:31:13.629975 140206359324544 ag_logging.py:145] Entity <bound method Conv.call of <tensorflow.python.layers.convolutional.Conv2D object at 0x7f83e26404e0>> could not be transformed and will be executed as-is. Please report this to the AutgoGraph team. When filing the bug, set the verbosity to 10 (on Linux, `export AUTOGRAPH_VERBOSITY=10`) and attach the full output. Cause: converting <bound method Conv.call of <tensorflow.python.layers.convolutional.Conv2D object at 0x7f83e26404e0>>: AssertionError: Bad argument number for Name: 3, expecting 4\n",
            "WARNING:tensorflow:Entity <bound method Conv.call of <tensorflow.python.layers.convolutional.Conv2D object at 0x7f83e1cb5080>> could not be transformed and will be executed as-is. Please report this to the AutgoGraph team. When filing the bug, set the verbosity to 10 (on Linux, `export AUTOGRAPH_VERBOSITY=10`) and attach the full output. Cause: converting <bound method Conv.call of <tensorflow.python.layers.convolutional.Conv2D object at 0x7f83e1cb5080>>: AssertionError: Bad argument number for Name: 3, expecting 4\n",
            "W0513 14:31:13.731336 140206359324544 ag_logging.py:145] Entity <bound method Conv.call of <tensorflow.python.layers.convolutional.Conv2D object at 0x7f83e1cb5080>> could not be transformed and will be executed as-is. Please report this to the AutgoGraph team. When filing the bug, set the verbosity to 10 (on Linux, `export AUTOGRAPH_VERBOSITY=10`) and attach the full output. Cause: converting <bound method Conv.call of <tensorflow.python.layers.convolutional.Conv2D object at 0x7f83e1cb5080>>: AssertionError: Bad argument number for Name: 3, expecting 4\n",
            "WARNING:tensorflow:Entity <bound method Conv.call of <tensorflow.python.layers.convolutional.Conv2D object at 0x7f83e2640518>> could not be transformed and will be executed as-is. Please report this to the AutgoGraph team. When filing the bug, set the verbosity to 10 (on Linux, `export AUTOGRAPH_VERBOSITY=10`) and attach the full output. Cause: converting <bound method Conv.call of <tensorflow.python.layers.convolutional.Conv2D object at 0x7f83e2640518>>: AssertionError: Bad argument number for Name: 3, expecting 4\n",
            "W0513 14:31:13.835516 140206359324544 ag_logging.py:145] Entity <bound method Conv.call of <tensorflow.python.layers.convolutional.Conv2D object at 0x7f83e2640518>> could not be transformed and will be executed as-is. Please report this to the AutgoGraph team. When filing the bug, set the verbosity to 10 (on Linux, `export AUTOGRAPH_VERBOSITY=10`) and attach the full output. Cause: converting <bound method Conv.call of <tensorflow.python.layers.convolutional.Conv2D object at 0x7f83e2640518>>: AssertionError: Bad argument number for Name: 3, expecting 4\n",
            "WARNING:tensorflow:Entity <bound method Conv.call of <tensorflow.python.layers.convolutional.Conv2D object at 0x7f83e2880978>> could not be transformed and will be executed as-is. Please report this to the AutgoGraph team. When filing the bug, set the verbosity to 10 (on Linux, `export AUTOGRAPH_VERBOSITY=10`) and attach the full output. Cause: converting <bound method Conv.call of <tensorflow.python.layers.convolutional.Conv2D object at 0x7f83e2880978>>: AssertionError: Bad argument number for Name: 3, expecting 4\n",
            "W0513 14:31:13.936879 140206359324544 ag_logging.py:145] Entity <bound method Conv.call of <tensorflow.python.layers.convolutional.Conv2D object at 0x7f83e2880978>> could not be transformed and will be executed as-is. Please report this to the AutgoGraph team. When filing the bug, set the verbosity to 10 (on Linux, `export AUTOGRAPH_VERBOSITY=10`) and attach the full output. Cause: converting <bound method Conv.call of <tensorflow.python.layers.convolutional.Conv2D object at 0x7f83e2880978>>: AssertionError: Bad argument number for Name: 3, expecting 4\n",
            "WARNING:tensorflow:Entity <bound method Conv.call of <tensorflow.python.layers.convolutional.Conv2D object at 0x7f83e2754e10>> could not be transformed and will be executed as-is. Please report this to the AutgoGraph team. When filing the bug, set the verbosity to 10 (on Linux, `export AUTOGRAPH_VERBOSITY=10`) and attach the full output. Cause: converting <bound method Conv.call of <tensorflow.python.layers.convolutional.Conv2D object at 0x7f83e2754e10>>: AssertionError: Bad argument number for Name: 3, expecting 4\n",
            "W0513 14:31:14.033703 140206359324544 ag_logging.py:145] Entity <bound method Conv.call of <tensorflow.python.layers.convolutional.Conv2D object at 0x7f83e2754e10>> could not be transformed and will be executed as-is. Please report this to the AutgoGraph team. When filing the bug, set the verbosity to 10 (on Linux, `export AUTOGRAPH_VERBOSITY=10`) and attach the full output. Cause: converting <bound method Conv.call of <tensorflow.python.layers.convolutional.Conv2D object at 0x7f83e2754e10>>: AssertionError: Bad argument number for Name: 3, expecting 4\n",
            "WARNING:tensorflow:Entity <bound method Conv.call of <tensorflow.python.layers.convolutional.Conv2D object at 0x7f83e2640518>> could not be transformed and will be executed as-is. Please report this to the AutgoGraph team. When filing the bug, set the verbosity to 10 (on Linux, `export AUTOGRAPH_VERBOSITY=10`) and attach the full output. Cause: converting <bound method Conv.call of <tensorflow.python.layers.convolutional.Conv2D object at 0x7f83e2640518>>: AssertionError: Bad argument number for Name: 3, expecting 4\n",
            "W0513 14:31:14.130621 140206359324544 ag_logging.py:145] Entity <bound method Conv.call of <tensorflow.python.layers.convolutional.Conv2D object at 0x7f83e2640518>> could not be transformed and will be executed as-is. Please report this to the AutgoGraph team. When filing the bug, set the verbosity to 10 (on Linux, `export AUTOGRAPH_VERBOSITY=10`) and attach the full output. Cause: converting <bound method Conv.call of <tensorflow.python.layers.convolutional.Conv2D object at 0x7f83e2640518>>: AssertionError: Bad argument number for Name: 3, expecting 4\n",
            "WARNING:tensorflow:Entity <bound method Conv.call of <tensorflow.python.layers.convolutional.Conv2D object at 0x7f83e2640438>> could not be transformed and will be executed as-is. Please report this to the AutgoGraph team. When filing the bug, set the verbosity to 10 (on Linux, `export AUTOGRAPH_VERBOSITY=10`) and attach the full output. Cause: converting <bound method Conv.call of <tensorflow.python.layers.convolutional.Conv2D object at 0x7f83e2640438>>: AssertionError: Bad argument number for Name: 3, expecting 4\n",
            "W0513 14:31:14.239117 140206359324544 ag_logging.py:145] Entity <bound method Conv.call of <tensorflow.python.layers.convolutional.Conv2D object at 0x7f83e2640438>> could not be transformed and will be executed as-is. Please report this to the AutgoGraph team. When filing the bug, set the verbosity to 10 (on Linux, `export AUTOGRAPH_VERBOSITY=10`) and attach the full output. Cause: converting <bound method Conv.call of <tensorflow.python.layers.convolutional.Conv2D object at 0x7f83e2640438>>: AssertionError: Bad argument number for Name: 3, expecting 4\n",
            "WARNING:tensorflow:Entity <bound method Conv.call of <tensorflow.python.layers.convolutional.Conv2D object at 0x7f83e1a96fd0>> could not be transformed and will be executed as-is. Please report this to the AutgoGraph team. When filing the bug, set the verbosity to 10 (on Linux, `export AUTOGRAPH_VERBOSITY=10`) and attach the full output. Cause: converting <bound method Conv.call of <tensorflow.python.layers.convolutional.Conv2D object at 0x7f83e1a96fd0>>: AssertionError: Bad argument number for Name: 3, expecting 4\n",
            "W0513 14:31:14.333066 140206359324544 ag_logging.py:145] Entity <bound method Conv.call of <tensorflow.python.layers.convolutional.Conv2D object at 0x7f83e1a96fd0>> could not be transformed and will be executed as-is. Please report this to the AutgoGraph team. When filing the bug, set the verbosity to 10 (on Linux, `export AUTOGRAPH_VERBOSITY=10`) and attach the full output. Cause: converting <bound method Conv.call of <tensorflow.python.layers.convolutional.Conv2D object at 0x7f83e1a96fd0>>: AssertionError: Bad argument number for Name: 3, expecting 4\n",
            "WARNING:tensorflow:From /content/models/research/object_detection/core/anchor_generator.py:171: The name tf.assert_equal is deprecated. Please use tf.compat.v1.assert_equal instead.\n",
            "\n",
            "W0513 14:31:15.097280 140206359324544 deprecation_wrapper.py:119] From /content/models/research/object_detection/core/anchor_generator.py:171: The name tf.assert_equal is deprecated. Please use tf.compat.v1.assert_equal instead.\n",
            "\n",
            "WARNING:tensorflow:From /content/models/research/object_detection/predictors/convolutional_box_predictor.py:157: The name tf.logging.info is deprecated. Please use tf.compat.v1.logging.info instead.\n",
            "\n",
            "W0513 14:31:15.113370 140206359324544 deprecation_wrapper.py:119] From /content/models/research/object_detection/predictors/convolutional_box_predictor.py:157: The name tf.logging.info is deprecated. Please use tf.compat.v1.logging.info instead.\n",
            "\n",
            "INFO:tensorflow:depth of additional conv before box predictor: 0\n",
            "I0513 14:31:15.113594 140206359324544 convolutional_box_predictor.py:158] depth of additional conv before box predictor: 0\n",
            "WARNING:tensorflow:Entity <bound method Conv.call of <tensorflow.python.layers.convolutional.Conv2D object at 0x7f83e14c9940>> could not be transformed and will be executed as-is. Please report this to the AutgoGraph team. When filing the bug, set the verbosity to 10 (on Linux, `export AUTOGRAPH_VERBOSITY=10`) and attach the full output. Cause: converting <bound method Conv.call of <tensorflow.python.layers.convolutional.Conv2D object at 0x7f83e14c9940>>: AssertionError: Bad argument number for Name: 3, expecting 4\n",
            "W0513 14:31:15.192760 140206359324544 ag_logging.py:145] Entity <bound method Conv.call of <tensorflow.python.layers.convolutional.Conv2D object at 0x7f83e14c9940>> could not be transformed and will be executed as-is. Please report this to the AutgoGraph team. When filing the bug, set the verbosity to 10 (on Linux, `export AUTOGRAPH_VERBOSITY=10`) and attach the full output. Cause: converting <bound method Conv.call of <tensorflow.python.layers.convolutional.Conv2D object at 0x7f83e14c9940>>: AssertionError: Bad argument number for Name: 3, expecting 4\n",
            "WARNING:tensorflow:Entity <bound method Conv.call of <tensorflow.python.layers.convolutional.Conv2D object at 0x7f83e14c99e8>> could not be transformed and will be executed as-is. Please report this to the AutgoGraph team. When filing the bug, set the verbosity to 10 (on Linux, `export AUTOGRAPH_VERBOSITY=10`) and attach the full output. Cause: converting <bound method Conv.call of <tensorflow.python.layers.convolutional.Conv2D object at 0x7f83e14c99e8>>: AssertionError: Bad argument number for Name: 3, expecting 4\n",
            "W0513 14:31:15.275579 140206359324544 ag_logging.py:145] Entity <bound method Conv.call of <tensorflow.python.layers.convolutional.Conv2D object at 0x7f83e14c99e8>> could not be transformed and will be executed as-is. Please report this to the AutgoGraph team. When filing the bug, set the verbosity to 10 (on Linux, `export AUTOGRAPH_VERBOSITY=10`) and attach the full output. Cause: converting <bound method Conv.call of <tensorflow.python.layers.convolutional.Conv2D object at 0x7f83e14c99e8>>: AssertionError: Bad argument number for Name: 3, expecting 4\n",
            "INFO:tensorflow:depth of additional conv before box predictor: 0\n",
            "I0513 14:31:15.280122 140206359324544 convolutional_box_predictor.py:158] depth of additional conv before box predictor: 0\n",
            "WARNING:tensorflow:Entity <bound method Conv.call of <tensorflow.python.layers.convolutional.Conv2D object at 0x7f83e14c9f28>> could not be transformed and will be executed as-is. Please report this to the AutgoGraph team. When filing the bug, set the verbosity to 10 (on Linux, `export AUTOGRAPH_VERBOSITY=10`) and attach the full output. Cause: converting <bound method Conv.call of <tensorflow.python.layers.convolutional.Conv2D object at 0x7f83e14c9f28>>: AssertionError: Bad argument number for Name: 3, expecting 4\n",
            "W0513 14:31:15.361233 140206359324544 ag_logging.py:145] Entity <bound method Conv.call of <tensorflow.python.layers.convolutional.Conv2D object at 0x7f83e14c9f28>> could not be transformed and will be executed as-is. Please report this to the AutgoGraph team. When filing the bug, set the verbosity to 10 (on Linux, `export AUTOGRAPH_VERBOSITY=10`) and attach the full output. Cause: converting <bound method Conv.call of <tensorflow.python.layers.convolutional.Conv2D object at 0x7f83e14c9f28>>: AssertionError: Bad argument number for Name: 3, expecting 4\n",
            "WARNING:tensorflow:Entity <bound method Conv.call of <tensorflow.python.layers.convolutional.Conv2D object at 0x7f83e14c9f28>> could not be transformed and will be executed as-is. Please report this to the AutgoGraph team. When filing the bug, set the verbosity to 10 (on Linux, `export AUTOGRAPH_VERBOSITY=10`) and attach the full output. Cause: converting <bound method Conv.call of <tensorflow.python.layers.convolutional.Conv2D object at 0x7f83e14c9f28>>: AssertionError: Bad argument number for Name: 3, expecting 4\n",
            "W0513 14:31:15.448740 140206359324544 ag_logging.py:145] Entity <bound method Conv.call of <tensorflow.python.layers.convolutional.Conv2D object at 0x7f83e14c9f28>> could not be transformed and will be executed as-is. Please report this to the AutgoGraph team. When filing the bug, set the verbosity to 10 (on Linux, `export AUTOGRAPH_VERBOSITY=10`) and attach the full output. Cause: converting <bound method Conv.call of <tensorflow.python.layers.convolutional.Conv2D object at 0x7f83e14c9f28>>: AssertionError: Bad argument number for Name: 3, expecting 4\n",
            "INFO:tensorflow:depth of additional conv before box predictor: 0\n",
            "I0513 14:31:15.453598 140206359324544 convolutional_box_predictor.py:158] depth of additional conv before box predictor: 0\n",
            "WARNING:tensorflow:Entity <bound method Conv.call of <tensorflow.python.layers.convolutional.Conv2D object at 0x7f83e14c9f28>> could not be transformed and will be executed as-is. Please report this to the AutgoGraph team. When filing the bug, set the verbosity to 10 (on Linux, `export AUTOGRAPH_VERBOSITY=10`) and attach the full output. Cause: converting <bound method Conv.call of <tensorflow.python.layers.convolutional.Conv2D object at 0x7f83e14c9f28>>: AssertionError: Bad argument number for Name: 3, expecting 4\n",
            "W0513 14:31:15.532536 140206359324544 ag_logging.py:145] Entity <bound method Conv.call of <tensorflow.python.layers.convolutional.Conv2D object at 0x7f83e14c9f28>> could not be transformed and will be executed as-is. Please report this to the AutgoGraph team. When filing the bug, set the verbosity to 10 (on Linux, `export AUTOGRAPH_VERBOSITY=10`) and attach the full output. Cause: converting <bound method Conv.call of <tensorflow.python.layers.convolutional.Conv2D object at 0x7f83e14c9f28>>: AssertionError: Bad argument number for Name: 3, expecting 4\n",
            "WARNING:tensorflow:Entity <bound method Conv.call of <tensorflow.python.layers.convolutional.Conv2D object at 0x7f83e1462e10>> could not be transformed and will be executed as-is. Please report this to the AutgoGraph team. When filing the bug, set the verbosity to 10 (on Linux, `export AUTOGRAPH_VERBOSITY=10`) and attach the full output. Cause: converting <bound method Conv.call of <tensorflow.python.layers.convolutional.Conv2D object at 0x7f83e1462e10>>: AssertionError: Bad argument number for Name: 3, expecting 4\n",
            "W0513 14:31:15.630347 140206359324544 ag_logging.py:145] Entity <bound method Conv.call of <tensorflow.python.layers.convolutional.Conv2D object at 0x7f83e1462e10>> could not be transformed and will be executed as-is. Please report this to the AutgoGraph team. When filing the bug, set the verbosity to 10 (on Linux, `export AUTOGRAPH_VERBOSITY=10`) and attach the full output. Cause: converting <bound method Conv.call of <tensorflow.python.layers.convolutional.Conv2D object at 0x7f83e1462e10>>: AssertionError: Bad argument number for Name: 3, expecting 4\n",
            "INFO:tensorflow:depth of additional conv before box predictor: 0\n",
            "I0513 14:31:15.634795 140206359324544 convolutional_box_predictor.py:158] depth of additional conv before box predictor: 0\n",
            "WARNING:tensorflow:Entity <bound method Conv.call of <tensorflow.python.layers.convolutional.Conv2D object at 0x7f83e1a5f8d0>> could not be transformed and will be executed as-is. Please report this to the AutgoGraph team. When filing the bug, set the verbosity to 10 (on Linux, `export AUTOGRAPH_VERBOSITY=10`) and attach the full output. Cause: converting <bound method Conv.call of <tensorflow.python.layers.convolutional.Conv2D object at 0x7f83e1a5f8d0>>: AssertionError: Bad argument number for Name: 3, expecting 4\n",
            "W0513 14:31:15.714584 140206359324544 ag_logging.py:145] Entity <bound method Conv.call of <tensorflow.python.layers.convolutional.Conv2D object at 0x7f83e1a5f8d0>> could not be transformed and will be executed as-is. Please report this to the AutgoGraph team. When filing the bug, set the verbosity to 10 (on Linux, `export AUTOGRAPH_VERBOSITY=10`) and attach the full output. Cause: converting <bound method Conv.call of <tensorflow.python.layers.convolutional.Conv2D object at 0x7f83e1a5f8d0>>: AssertionError: Bad argument number for Name: 3, expecting 4\n",
            "WARNING:tensorflow:Entity <bound method Conv.call of <tensorflow.python.layers.convolutional.Conv2D object at 0x7f83e1a5fa20>> could not be transformed and will be executed as-is. Please report this to the AutgoGraph team. When filing the bug, set the verbosity to 10 (on Linux, `export AUTOGRAPH_VERBOSITY=10`) and attach the full output. Cause: converting <bound method Conv.call of <tensorflow.python.layers.convolutional.Conv2D object at 0x7f83e1a5fa20>>: AssertionError: Bad argument number for Name: 3, expecting 4\n",
            "W0513 14:31:15.809986 140206359324544 ag_logging.py:145] Entity <bound method Conv.call of <tensorflow.python.layers.convolutional.Conv2D object at 0x7f83e1a5fa20>> could not be transformed and will be executed as-is. Please report this to the AutgoGraph team. When filing the bug, set the verbosity to 10 (on Linux, `export AUTOGRAPH_VERBOSITY=10`) and attach the full output. Cause: converting <bound method Conv.call of <tensorflow.python.layers.convolutional.Conv2D object at 0x7f83e1a5fa20>>: AssertionError: Bad argument number for Name: 3, expecting 4\n",
            "INFO:tensorflow:depth of additional conv before box predictor: 0\n",
            "I0513 14:31:15.815124 140206359324544 convolutional_box_predictor.py:158] depth of additional conv before box predictor: 0\n",
            "WARNING:tensorflow:Entity <bound method Conv.call of <tensorflow.python.layers.convolutional.Conv2D object at 0x7f83e1a5f8d0>> could not be transformed and will be executed as-is. Please report this to the AutgoGraph team. When filing the bug, set the verbosity to 10 (on Linux, `export AUTOGRAPH_VERBOSITY=10`) and attach the full output. Cause: converting <bound method Conv.call of <tensorflow.python.layers.convolutional.Conv2D object at 0x7f83e1a5f8d0>>: AssertionError: Bad argument number for Name: 3, expecting 4\n",
            "W0513 14:31:15.908239 140206359324544 ag_logging.py:145] Entity <bound method Conv.call of <tensorflow.python.layers.convolutional.Conv2D object at 0x7f83e1a5f8d0>> could not be transformed and will be executed as-is. Please report this to the AutgoGraph team. When filing the bug, set the verbosity to 10 (on Linux, `export AUTOGRAPH_VERBOSITY=10`) and attach the full output. Cause: converting <bound method Conv.call of <tensorflow.python.layers.convolutional.Conv2D object at 0x7f83e1a5f8d0>>: AssertionError: Bad argument number for Name: 3, expecting 4\n",
            "WARNING:tensorflow:Entity <bound method Conv.call of <tensorflow.python.layers.convolutional.Conv2D object at 0x7f83e19e67b8>> could not be transformed and will be executed as-is. Please report this to the AutgoGraph team. When filing the bug, set the verbosity to 10 (on Linux, `export AUTOGRAPH_VERBOSITY=10`) and attach the full output. Cause: converting <bound method Conv.call of <tensorflow.python.layers.convolutional.Conv2D object at 0x7f83e19e67b8>>: AssertionError: Bad argument number for Name: 3, expecting 4\n",
            "W0513 14:31:15.990943 140206359324544 ag_logging.py:145] Entity <bound method Conv.call of <tensorflow.python.layers.convolutional.Conv2D object at 0x7f83e19e67b8>> could not be transformed and will be executed as-is. Please report this to the AutgoGraph team. When filing the bug, set the verbosity to 10 (on Linux, `export AUTOGRAPH_VERBOSITY=10`) and attach the full output. Cause: converting <bound method Conv.call of <tensorflow.python.layers.convolutional.Conv2D object at 0x7f83e19e67b8>>: AssertionError: Bad argument number for Name: 3, expecting 4\n",
            "INFO:tensorflow:depth of additional conv before box predictor: 0\n",
            "I0513 14:31:15.995723 140206359324544 convolutional_box_predictor.py:158] depth of additional conv before box predictor: 0\n",
            "WARNING:tensorflow:Entity <bound method Conv.call of <tensorflow.python.layers.convolutional.Conv2D object at 0x7f83e14c9908>> could not be transformed and will be executed as-is. Please report this to the AutgoGraph team. When filing the bug, set the verbosity to 10 (on Linux, `export AUTOGRAPH_VERBOSITY=10`) and attach the full output. Cause: converting <bound method Conv.call of <tensorflow.python.layers.convolutional.Conv2D object at 0x7f83e14c9908>>: AssertionError: Bad argument number for Name: 3, expecting 4\n",
            "W0513 14:31:16.080659 140206359324544 ag_logging.py:145] Entity <bound method Conv.call of <tensorflow.python.layers.convolutional.Conv2D object at 0x7f83e14c9908>> could not be transformed and will be executed as-is. Please report this to the AutgoGraph team. When filing the bug, set the verbosity to 10 (on Linux, `export AUTOGRAPH_VERBOSITY=10`) and attach the full output. Cause: converting <bound method Conv.call of <tensorflow.python.layers.convolutional.Conv2D object at 0x7f83e14c9908>>: AssertionError: Bad argument number for Name: 3, expecting 4\n",
            "WARNING:tensorflow:Entity <bound method Conv.call of <tensorflow.python.layers.convolutional.Conv2D object at 0x7f83e19c6588>> could not be transformed and will be executed as-is. Please report this to the AutgoGraph team. When filing the bug, set the verbosity to 10 (on Linux, `export AUTOGRAPH_VERBOSITY=10`) and attach the full output. Cause: converting <bound method Conv.call of <tensorflow.python.layers.convolutional.Conv2D object at 0x7f83e19c6588>>: AssertionError: Bad argument number for Name: 3, expecting 4\n",
            "W0513 14:31:16.166046 140206359324544 ag_logging.py:145] Entity <bound method Conv.call of <tensorflow.python.layers.convolutional.Conv2D object at 0x7f83e19c6588>> could not be transformed and will be executed as-is. Please report this to the AutgoGraph team. When filing the bug, set the verbosity to 10 (on Linux, `export AUTOGRAPH_VERBOSITY=10`) and attach the full output. Cause: converting <bound method Conv.call of <tensorflow.python.layers.convolutional.Conv2D object at 0x7f83e19c6588>>: AssertionError: Bad argument number for Name: 3, expecting 4\n",
            "WARNING:tensorflow:From /content/models/research/object_detection/export_tflite_ssd_graph_lib.py:53: The name tf.Session is deprecated. Please use tf.compat.v1.Session instead.\n",
            "\n",
            "W0513 14:31:16.188736 140206359324544 deprecation_wrapper.py:119] From /content/models/research/object_detection/export_tflite_ssd_graph_lib.py:53: The name tf.Session is deprecated. Please use tf.compat.v1.Session instead.\n",
            "\n",
            "2020-05-13 14:31:16.190187: I tensorflow/stream_executor/platform/default/dso_loader.cc:42] Successfully opened dynamic library libcuda.so.1\n",
            "2020-05-13 14:31:16.246854: I tensorflow/stream_executor/cuda/cuda_gpu_executor.cc:1005] successful NUMA node read from SysFS had negative value (-1), but there must be at least one NUMA node, so returning NUMA node zero\n",
            "2020-05-13 14:31:16.247613: I tensorflow/core/common_runtime/gpu/gpu_device.cc:1640] Found device 0 with properties: \n",
            "name: Tesla K80 major: 3 minor: 7 memoryClockRate(GHz): 0.8235\n",
            "pciBusID: 0000:00:04.0\n",
            "2020-05-13 14:31:16.284988: I tensorflow/stream_executor/platform/default/dso_loader.cc:42] Successfully opened dynamic library libcudart.so.10.0\n",
            "2020-05-13 14:31:16.582264: I tensorflow/stream_executor/platform/default/dso_loader.cc:42] Successfully opened dynamic library libcublas.so.10.0\n",
            "2020-05-13 14:31:16.736637: I tensorflow/stream_executor/platform/default/dso_loader.cc:42] Successfully opened dynamic library libcufft.so.10.0\n",
            "2020-05-13 14:31:16.804753: I tensorflow/stream_executor/platform/default/dso_loader.cc:42] Successfully opened dynamic library libcurand.so.10.0\n",
            "2020-05-13 14:31:17.141344: I tensorflow/stream_executor/platform/default/dso_loader.cc:42] Successfully opened dynamic library libcusolver.so.10.0\n",
            "2020-05-13 14:31:17.359305: I tensorflow/stream_executor/platform/default/dso_loader.cc:42] Successfully opened dynamic library libcusparse.so.10.0\n",
            "2020-05-13 14:31:18.040225: I tensorflow/stream_executor/platform/default/dso_loader.cc:42] Successfully opened dynamic library libcudnn.so.7\n",
            "2020-05-13 14:31:18.040532: I tensorflow/stream_executor/cuda/cuda_gpu_executor.cc:1005] successful NUMA node read from SysFS had negative value (-1), but there must be at least one NUMA node, so returning NUMA node zero\n",
            "2020-05-13 14:31:18.041472: I tensorflow/stream_executor/cuda/cuda_gpu_executor.cc:1005] successful NUMA node read from SysFS had negative value (-1), but there must be at least one NUMA node, so returning NUMA node zero\n",
            "2020-05-13 14:31:18.042242: I tensorflow/core/common_runtime/gpu/gpu_device.cc:1763] Adding visible gpu devices: 0\n",
            "2020-05-13 14:31:18.042820: I tensorflow/core/platform/cpu_feature_guard.cc:142] Your CPU supports instructions that this TensorFlow binary was not compiled to use: AVX2 FMA\n",
            "2020-05-13 14:31:18.139732: I tensorflow/stream_executor/cuda/cuda_gpu_executor.cc:1005] successful NUMA node read from SysFS had negative value (-1), but there must be at least one NUMA node, so returning NUMA node zero\n",
            "2020-05-13 14:31:18.140794: I tensorflow/compiler/xla/service/service.cc:168] XLA service 0x28d9480 executing computations on platform CUDA. Devices:\n",
            "2020-05-13 14:31:18.140857: I tensorflow/compiler/xla/service/service.cc:175]   StreamExecutor device (0): Tesla K80, Compute Capability 3.7\n",
            "2020-05-13 14:31:18.144869: I tensorflow/core/platform/profile_utils/cpu_utils.cc:94] CPU Frequency: 2300000000 Hz\n",
            "2020-05-13 14:31:18.145181: I tensorflow/compiler/xla/service/service.cc:168] XLA service 0x28d8a00 executing computations on platform Host. Devices:\n",
            "2020-05-13 14:31:18.145222: I tensorflow/compiler/xla/service/service.cc:175]   StreamExecutor device (0): <undefined>, <undefined>\n",
            "2020-05-13 14:31:18.145556: I tensorflow/stream_executor/cuda/cuda_gpu_executor.cc:1005] successful NUMA node read from SysFS had negative value (-1), but there must be at least one NUMA node, so returning NUMA node zero\n",
            "2020-05-13 14:31:18.146323: I tensorflow/core/common_runtime/gpu/gpu_device.cc:1640] Found device 0 with properties: \n",
            "name: Tesla K80 major: 3 minor: 7 memoryClockRate(GHz): 0.8235\n",
            "pciBusID: 0000:00:04.0\n",
            "2020-05-13 14:31:18.146456: I tensorflow/stream_executor/platform/default/dso_loader.cc:42] Successfully opened dynamic library libcudart.so.10.0\n",
            "2020-05-13 14:31:18.146521: I tensorflow/stream_executor/platform/default/dso_loader.cc:42] Successfully opened dynamic library libcublas.so.10.0\n",
            "2020-05-13 14:31:18.146583: I tensorflow/stream_executor/platform/default/dso_loader.cc:42] Successfully opened dynamic library libcufft.so.10.0\n",
            "2020-05-13 14:31:18.146640: I tensorflow/stream_executor/platform/default/dso_loader.cc:42] Successfully opened dynamic library libcurand.so.10.0\n",
            "2020-05-13 14:31:18.146693: I tensorflow/stream_executor/platform/default/dso_loader.cc:42] Successfully opened dynamic library libcusolver.so.10.0\n",
            "2020-05-13 14:31:18.146758: I tensorflow/stream_executor/platform/default/dso_loader.cc:42] Successfully opened dynamic library libcusparse.so.10.0\n",
            "2020-05-13 14:31:18.146817: I tensorflow/stream_executor/platform/default/dso_loader.cc:42] Successfully opened dynamic library libcudnn.so.7\n",
            "2020-05-13 14:31:18.146988: I tensorflow/stream_executor/cuda/cuda_gpu_executor.cc:1005] successful NUMA node read from SysFS had negative value (-1), but there must be at least one NUMA node, so returning NUMA node zero\n",
            "2020-05-13 14:31:18.147782: I tensorflow/stream_executor/cuda/cuda_gpu_executor.cc:1005] successful NUMA node read from SysFS had negative value (-1), but there must be at least one NUMA node, so returning NUMA node zero\n",
            "2020-05-13 14:31:18.148520: I tensorflow/core/common_runtime/gpu/gpu_device.cc:1763] Adding visible gpu devices: 0\n",
            "2020-05-13 14:31:18.148624: I tensorflow/stream_executor/platform/default/dso_loader.cc:42] Successfully opened dynamic library libcudart.so.10.0\n",
            "2020-05-13 14:31:18.150421: I tensorflow/core/common_runtime/gpu/gpu_device.cc:1181] Device interconnect StreamExecutor with strength 1 edge matrix:\n",
            "2020-05-13 14:31:18.150457: I tensorflow/core/common_runtime/gpu/gpu_device.cc:1187]      0 \n",
            "2020-05-13 14:31:18.150477: I tensorflow/core/common_runtime/gpu/gpu_device.cc:1200] 0:   N \n",
            "2020-05-13 14:31:18.150658: I tensorflow/stream_executor/cuda/cuda_gpu_executor.cc:1005] successful NUMA node read from SysFS had negative value (-1), but there must be at least one NUMA node, so returning NUMA node zero\n",
            "2020-05-13 14:31:18.151478: I tensorflow/stream_executor/cuda/cuda_gpu_executor.cc:1005] successful NUMA node read from SysFS had negative value (-1), but there must be at least one NUMA node, so returning NUMA node zero\n",
            "2020-05-13 14:31:18.152246: W tensorflow/core/common_runtime/gpu/gpu_bfc_allocator.cc:40] Overriding allow_growth setting because the TF_FORCE_GPU_ALLOW_GROWTH environment variable is set. Original config value was 0.\n",
            "2020-05-13 14:31:18.152383: I tensorflow/core/common_runtime/gpu/gpu_device.cc:1326] Created TensorFlow device (/job:localhost/replica:0/task:0/device:GPU:0 with 10805 MB memory) -> physical GPU (device: 0, name: Tesla K80, pci bus id: 0000:00:04.0, compute capability: 3.7)\n",
            "WARNING:tensorflow:From /content/models/research/object_detection/export_tflite_ssd_graph_lib.py:268: The name tf.train.get_or_create_global_step is deprecated. Please use tf.compat.v1.train.get_or_create_global_step instead.\n",
            "\n",
            "W0513 14:31:18.678928 140206359324544 deprecation_wrapper.py:119] From /content/models/research/object_detection/export_tflite_ssd_graph_lib.py:268: The name tf.train.get_or_create_global_step is deprecated. Please use tf.compat.v1.train.get_or_create_global_step instead.\n",
            "\n",
            "WARNING:tensorflow:From /content/models/research/object_detection/builders/graph_rewriter_builder.py:50: The name tf.get_default_graph is deprecated. Please use tf.compat.v1.get_default_graph instead.\n",
            "\n",
            "W0513 14:31:18.683674 140206359324544 deprecation_wrapper.py:119] From /content/models/research/object_detection/builders/graph_rewriter_builder.py:50: The name tf.get_default_graph is deprecated. Please use tf.compat.v1.get_default_graph instead.\n",
            "\n",
            "INFO:tensorflow:Skipping quant after FeatureExtractor/MobilenetV1/MobilenetV1/Conv2d_0/add_fold\n",
            "I0513 14:31:20.049477 140206359324544 quantize.py:298] Skipping quant after FeatureExtractor/MobilenetV1/MobilenetV1/Conv2d_0/add_fold\n",
            "INFO:tensorflow:Skipping quant after FeatureExtractor/MobilenetV1/MobilenetV1/Conv2d_1_depthwise/add_fold\n",
            "I0513 14:31:20.049952 140206359324544 quantize.py:298] Skipping quant after FeatureExtractor/MobilenetV1/MobilenetV1/Conv2d_1_depthwise/add_fold\n",
            "INFO:tensorflow:Skipping quant after FeatureExtractor/MobilenetV1/MobilenetV1/Conv2d_1_pointwise/add_fold\n",
            "I0513 14:31:20.050263 140206359324544 quantize.py:298] Skipping quant after FeatureExtractor/MobilenetV1/MobilenetV1/Conv2d_1_pointwise/add_fold\n",
            "INFO:tensorflow:Skipping quant after FeatureExtractor/MobilenetV1/MobilenetV1/Conv2d_2_depthwise/add_fold\n",
            "I0513 14:31:20.050597 140206359324544 quantize.py:298] Skipping quant after FeatureExtractor/MobilenetV1/MobilenetV1/Conv2d_2_depthwise/add_fold\n",
            "INFO:tensorflow:Skipping quant after FeatureExtractor/MobilenetV1/MobilenetV1/Conv2d_2_pointwise/add_fold\n",
            "I0513 14:31:20.050970 140206359324544 quantize.py:298] Skipping quant after FeatureExtractor/MobilenetV1/MobilenetV1/Conv2d_2_pointwise/add_fold\n",
            "INFO:tensorflow:Skipping quant after FeatureExtractor/MobilenetV1/MobilenetV1/Conv2d_3_depthwise/add_fold\n",
            "I0513 14:31:20.051265 140206359324544 quantize.py:298] Skipping quant after FeatureExtractor/MobilenetV1/MobilenetV1/Conv2d_3_depthwise/add_fold\n",
            "INFO:tensorflow:Skipping quant after FeatureExtractor/MobilenetV1/MobilenetV1/Conv2d_3_pointwise/add_fold\n",
            "I0513 14:31:20.051552 140206359324544 quantize.py:298] Skipping quant after FeatureExtractor/MobilenetV1/MobilenetV1/Conv2d_3_pointwise/add_fold\n",
            "INFO:tensorflow:Skipping quant after FeatureExtractor/MobilenetV1/MobilenetV1/Conv2d_4_depthwise/add_fold\n",
            "I0513 14:31:20.051848 140206359324544 quantize.py:298] Skipping quant after FeatureExtractor/MobilenetV1/MobilenetV1/Conv2d_4_depthwise/add_fold\n",
            "INFO:tensorflow:Skipping quant after FeatureExtractor/MobilenetV1/MobilenetV1/Conv2d_4_pointwise/add_fold\n",
            "I0513 14:31:20.052171 140206359324544 quantize.py:298] Skipping quant after FeatureExtractor/MobilenetV1/MobilenetV1/Conv2d_4_pointwise/add_fold\n",
            "INFO:tensorflow:Skipping quant after FeatureExtractor/MobilenetV1/MobilenetV1/Conv2d_5_depthwise/add_fold\n",
            "I0513 14:31:20.052445 140206359324544 quantize.py:298] Skipping quant after FeatureExtractor/MobilenetV1/MobilenetV1/Conv2d_5_depthwise/add_fold\n",
            "INFO:tensorflow:Skipping quant after FeatureExtractor/MobilenetV1/MobilenetV1/Conv2d_5_pointwise/add_fold\n",
            "I0513 14:31:20.052729 140206359324544 quantize.py:298] Skipping quant after FeatureExtractor/MobilenetV1/MobilenetV1/Conv2d_5_pointwise/add_fold\n",
            "INFO:tensorflow:Skipping quant after FeatureExtractor/MobilenetV1/MobilenetV1/Conv2d_6_depthwise/add_fold\n",
            "I0513 14:31:20.053154 140206359324544 quantize.py:298] Skipping quant after FeatureExtractor/MobilenetV1/MobilenetV1/Conv2d_6_depthwise/add_fold\n",
            "INFO:tensorflow:Skipping quant after FeatureExtractor/MobilenetV1/MobilenetV1/Conv2d_6_pointwise/add_fold\n",
            "I0513 14:31:20.053467 140206359324544 quantize.py:298] Skipping quant after FeatureExtractor/MobilenetV1/MobilenetV1/Conv2d_6_pointwise/add_fold\n",
            "INFO:tensorflow:Skipping quant after FeatureExtractor/MobilenetV1/MobilenetV1/Conv2d_7_depthwise/add_fold\n",
            "I0513 14:31:20.053740 140206359324544 quantize.py:298] Skipping quant after FeatureExtractor/MobilenetV1/MobilenetV1/Conv2d_7_depthwise/add_fold\n",
            "INFO:tensorflow:Skipping quant after FeatureExtractor/MobilenetV1/MobilenetV1/Conv2d_7_pointwise/add_fold\n",
            "I0513 14:31:20.054068 140206359324544 quantize.py:298] Skipping quant after FeatureExtractor/MobilenetV1/MobilenetV1/Conv2d_7_pointwise/add_fold\n",
            "INFO:tensorflow:Skipping quant after FeatureExtractor/MobilenetV1/MobilenetV1/Conv2d_8_depthwise/add_fold\n",
            "I0513 14:31:20.054335 140206359324544 quantize.py:298] Skipping quant after FeatureExtractor/MobilenetV1/MobilenetV1/Conv2d_8_depthwise/add_fold\n",
            "INFO:tensorflow:Skipping quant after FeatureExtractor/MobilenetV1/MobilenetV1/Conv2d_8_pointwise/add_fold\n",
            "I0513 14:31:20.054591 140206359324544 quantize.py:298] Skipping quant after FeatureExtractor/MobilenetV1/MobilenetV1/Conv2d_8_pointwise/add_fold\n",
            "INFO:tensorflow:Skipping quant after FeatureExtractor/MobilenetV1/MobilenetV1/Conv2d_9_depthwise/add_fold\n",
            "I0513 14:31:20.054931 140206359324544 quantize.py:298] Skipping quant after FeatureExtractor/MobilenetV1/MobilenetV1/Conv2d_9_depthwise/add_fold\n",
            "INFO:tensorflow:Skipping quant after FeatureExtractor/MobilenetV1/MobilenetV1/Conv2d_9_pointwise/add_fold\n",
            "I0513 14:31:20.055187 140206359324544 quantize.py:298] Skipping quant after FeatureExtractor/MobilenetV1/MobilenetV1/Conv2d_9_pointwise/add_fold\n",
            "INFO:tensorflow:Skipping quant after FeatureExtractor/MobilenetV1/MobilenetV1/Conv2d_10_depthwise/add_fold\n",
            "I0513 14:31:20.055481 140206359324544 quantize.py:298] Skipping quant after FeatureExtractor/MobilenetV1/MobilenetV1/Conv2d_10_depthwise/add_fold\n",
            "INFO:tensorflow:Skipping quant after FeatureExtractor/MobilenetV1/MobilenetV1/Conv2d_10_pointwise/add_fold\n",
            "I0513 14:31:20.055741 140206359324544 quantize.py:298] Skipping quant after FeatureExtractor/MobilenetV1/MobilenetV1/Conv2d_10_pointwise/add_fold\n",
            "INFO:tensorflow:Skipping quant after FeatureExtractor/MobilenetV1/MobilenetV1/Conv2d_11_depthwise/add_fold\n",
            "I0513 14:31:20.056073 140206359324544 quantize.py:298] Skipping quant after FeatureExtractor/MobilenetV1/MobilenetV1/Conv2d_11_depthwise/add_fold\n",
            "INFO:tensorflow:Skipping quant after FeatureExtractor/MobilenetV1/MobilenetV1/Conv2d_11_pointwise/add_fold\n",
            "I0513 14:31:20.056325 140206359324544 quantize.py:298] Skipping quant after FeatureExtractor/MobilenetV1/MobilenetV1/Conv2d_11_pointwise/add_fold\n",
            "INFO:tensorflow:Skipping quant after FeatureExtractor/MobilenetV1/MobilenetV1/Conv2d_12_depthwise/add_fold\n",
            "I0513 14:31:20.056608 140206359324544 quantize.py:298] Skipping quant after FeatureExtractor/MobilenetV1/MobilenetV1/Conv2d_12_depthwise/add_fold\n",
            "INFO:tensorflow:Skipping quant after FeatureExtractor/MobilenetV1/MobilenetV1/Conv2d_12_pointwise/add_fold\n",
            "I0513 14:31:20.056885 140206359324544 quantize.py:298] Skipping quant after FeatureExtractor/MobilenetV1/MobilenetV1/Conv2d_12_pointwise/add_fold\n",
            "INFO:tensorflow:Skipping quant after FeatureExtractor/MobilenetV1/MobilenetV1/Conv2d_13_depthwise/add_fold\n",
            "I0513 14:31:20.057155 140206359324544 quantize.py:298] Skipping quant after FeatureExtractor/MobilenetV1/MobilenetV1/Conv2d_13_depthwise/add_fold\n",
            "INFO:tensorflow:Skipping quant after FeatureExtractor/MobilenetV1/MobilenetV1/Conv2d_13_pointwise/add_fold\n",
            "I0513 14:31:20.057413 140206359324544 quantize.py:298] Skipping quant after FeatureExtractor/MobilenetV1/MobilenetV1/Conv2d_13_pointwise/add_fold\n",
            "INFO:tensorflow:Skipping quant after FeatureExtractor/MobilenetV1/Conv2d_13_pointwise_1_Conv2d_2_1x1_192/add_fold\n",
            "I0513 14:31:20.057678 140206359324544 quantize.py:298] Skipping quant after FeatureExtractor/MobilenetV1/Conv2d_13_pointwise_1_Conv2d_2_1x1_192/add_fold\n",
            "INFO:tensorflow:Skipping quant after FeatureExtractor/MobilenetV1/Conv2d_13_pointwise_2_Conv2d_2_3x3_s2_384/add_fold\n",
            "I0513 14:31:20.057991 140206359324544 quantize.py:298] Skipping quant after FeatureExtractor/MobilenetV1/Conv2d_13_pointwise_2_Conv2d_2_3x3_s2_384/add_fold\n",
            "INFO:tensorflow:Skipping quant after FeatureExtractor/MobilenetV1/Conv2d_13_pointwise_1_Conv2d_3_1x1_96/add_fold\n",
            "I0513 14:31:20.058264 140206359324544 quantize.py:298] Skipping quant after FeatureExtractor/MobilenetV1/Conv2d_13_pointwise_1_Conv2d_3_1x1_96/add_fold\n",
            "INFO:tensorflow:Skipping quant after FeatureExtractor/MobilenetV1/Conv2d_13_pointwise_2_Conv2d_3_3x3_s2_192/add_fold\n",
            "I0513 14:31:20.058550 140206359324544 quantize.py:298] Skipping quant after FeatureExtractor/MobilenetV1/Conv2d_13_pointwise_2_Conv2d_3_3x3_s2_192/add_fold\n",
            "INFO:tensorflow:Skipping quant after FeatureExtractor/MobilenetV1/Conv2d_13_pointwise_1_Conv2d_4_1x1_96/add_fold\n",
            "I0513 14:31:20.058888 140206359324544 quantize.py:298] Skipping quant after FeatureExtractor/MobilenetV1/Conv2d_13_pointwise_1_Conv2d_4_1x1_96/add_fold\n",
            "INFO:tensorflow:Skipping quant after FeatureExtractor/MobilenetV1/Conv2d_13_pointwise_2_Conv2d_4_3x3_s2_192/add_fold\n",
            "I0513 14:31:20.059171 140206359324544 quantize.py:298] Skipping quant after FeatureExtractor/MobilenetV1/Conv2d_13_pointwise_2_Conv2d_4_3x3_s2_192/add_fold\n",
            "INFO:tensorflow:Skipping quant after FeatureExtractor/MobilenetV1/Conv2d_13_pointwise_1_Conv2d_5_1x1_48/add_fold\n",
            "I0513 14:31:20.059468 140206359324544 quantize.py:298] Skipping quant after FeatureExtractor/MobilenetV1/Conv2d_13_pointwise_1_Conv2d_5_1x1_48/add_fold\n",
            "INFO:tensorflow:Skipping quant after FeatureExtractor/MobilenetV1/Conv2d_13_pointwise_2_Conv2d_5_3x3_s2_96/add_fold\n",
            "I0513 14:31:20.059722 140206359324544 quantize.py:298] Skipping quant after FeatureExtractor/MobilenetV1/Conv2d_13_pointwise_2_Conv2d_5_3x3_s2_96/add_fold\n",
            "WARNING:tensorflow:From /content/models/research/object_detection/export_tflite_ssd_graph_lib.py:293: The name tf.train.Saver is deprecated. Please use tf.compat.v1.train.Saver instead.\n",
            "\n",
            "W0513 14:31:20.061557 140206359324544 deprecation_wrapper.py:119] From /content/models/research/object_detection/export_tflite_ssd_graph_lib.py:293: The name tf.train.Saver is deprecated. Please use tf.compat.v1.train.Saver instead.\n",
            "\n",
            "WARNING:tensorflow:From /usr/local/lib/python3.6/dist-packages/tensorflow/python/tools/freeze_graph.py:127: checkpoint_exists (from tensorflow.python.training.checkpoint_management) is deprecated and will be removed in a future version.\n",
            "Instructions for updating:\n",
            "Use standard file APIs to check for files with this prefix.\n",
            "W0513 14:31:20.494610 140206359324544 deprecation.py:323] From /usr/local/lib/python3.6/dist-packages/tensorflow/python/tools/freeze_graph.py:127: checkpoint_exists (from tensorflow.python.training.checkpoint_management) is deprecated and will be removed in a future version.\n",
            "Instructions for updating:\n",
            "Use standard file APIs to check for files with this prefix.\n",
            "2020-05-13 14:31:21.278363: I tensorflow/stream_executor/cuda/cuda_gpu_executor.cc:1005] successful NUMA node read from SysFS had negative value (-1), but there must be at least one NUMA node, so returning NUMA node zero\n",
            "2020-05-13 14:31:21.279271: I tensorflow/core/common_runtime/gpu/gpu_device.cc:1640] Found device 0 with properties: \n",
            "name: Tesla K80 major: 3 minor: 7 memoryClockRate(GHz): 0.8235\n",
            "pciBusID: 0000:00:04.0\n",
            "2020-05-13 14:31:21.279395: I tensorflow/stream_executor/platform/default/dso_loader.cc:42] Successfully opened dynamic library libcudart.so.10.0\n",
            "2020-05-13 14:31:21.279463: I tensorflow/stream_executor/platform/default/dso_loader.cc:42] Successfully opened dynamic library libcublas.so.10.0\n",
            "2020-05-13 14:31:21.279518: I tensorflow/stream_executor/platform/default/dso_loader.cc:42] Successfully opened dynamic library libcufft.so.10.0\n",
            "2020-05-13 14:31:21.279576: I tensorflow/stream_executor/platform/default/dso_loader.cc:42] Successfully opened dynamic library libcurand.so.10.0\n",
            "2020-05-13 14:31:21.279627: I tensorflow/stream_executor/platform/default/dso_loader.cc:42] Successfully opened dynamic library libcusolver.so.10.0\n",
            "2020-05-13 14:31:21.279698: I tensorflow/stream_executor/platform/default/dso_loader.cc:42] Successfully opened dynamic library libcusparse.so.10.0\n",
            "2020-05-13 14:31:21.279751: I tensorflow/stream_executor/platform/default/dso_loader.cc:42] Successfully opened dynamic library libcudnn.so.7\n",
            "2020-05-13 14:31:21.279928: I tensorflow/stream_executor/cuda/cuda_gpu_executor.cc:1005] successful NUMA node read from SysFS had negative value (-1), but there must be at least one NUMA node, so returning NUMA node zero\n",
            "2020-05-13 14:31:21.280720: I tensorflow/stream_executor/cuda/cuda_gpu_executor.cc:1005] successful NUMA node read from SysFS had negative value (-1), but there must be at least one NUMA node, so returning NUMA node zero\n",
            "2020-05-13 14:31:21.281451: I tensorflow/core/common_runtime/gpu/gpu_device.cc:1763] Adding visible gpu devices: 0\n",
            "2020-05-13 14:31:21.281507: I tensorflow/core/common_runtime/gpu/gpu_device.cc:1181] Device interconnect StreamExecutor with strength 1 edge matrix:\n",
            "2020-05-13 14:31:21.281528: I tensorflow/core/common_runtime/gpu/gpu_device.cc:1187]      0 \n",
            "2020-05-13 14:31:21.281546: I tensorflow/core/common_runtime/gpu/gpu_device.cc:1200] 0:   N \n",
            "2020-05-13 14:31:21.281749: I tensorflow/stream_executor/cuda/cuda_gpu_executor.cc:1005] successful NUMA node read from SysFS had negative value (-1), but there must be at least one NUMA node, so returning NUMA node zero\n",
            "2020-05-13 14:31:21.282560: I tensorflow/stream_executor/cuda/cuda_gpu_executor.cc:1005] successful NUMA node read from SysFS had negative value (-1), but there must be at least one NUMA node, so returning NUMA node zero\n",
            "2020-05-13 14:31:21.283413: I tensorflow/core/common_runtime/gpu/gpu_device.cc:1326] Created TensorFlow device (/job:localhost/replica:0/task:0/device:GPU:0 with 10805 MB memory) -> physical GPU (device: 0, name: Tesla K80, pci bus id: 0000:00:04.0, compute capability: 3.7)\n",
            "INFO:tensorflow:Restoring parameters from /content/sample_data/train_model.ckpt-2000\n",
            "I0513 14:31:21.285189 140206359324544 saver.py:1280] Restoring parameters from /content/sample_data/train_model.ckpt-2000\n",
            "WARNING:tensorflow:From /usr/local/lib/python3.6/dist-packages/tensorflow/python/tools/freeze_graph.py:233: convert_variables_to_constants (from tensorflow.python.framework.graph_util_impl) is deprecated and will be removed in a future version.\n",
            "Instructions for updating:\n",
            "Use `tf.compat.v1.graph_util.convert_variables_to_constants`\n",
            "W0513 14:31:21.941924 140206359324544 deprecation.py:323] From /usr/local/lib/python3.6/dist-packages/tensorflow/python/tools/freeze_graph.py:233: convert_variables_to_constants (from tensorflow.python.framework.graph_util_impl) is deprecated and will be removed in a future version.\n",
            "Instructions for updating:\n",
            "Use `tf.compat.v1.graph_util.convert_variables_to_constants`\n",
            "WARNING:tensorflow:From /usr/local/lib/python3.6/dist-packages/tensorflow/python/framework/graph_util_impl.py:270: extract_sub_graph (from tensorflow.python.framework.graph_util_impl) is deprecated and will be removed in a future version.\n",
            "Instructions for updating:\n",
            "Use `tf.compat.v1.graph_util.extract_sub_graph`\n",
            "W0513 14:31:21.942249 140206359324544 deprecation.py:323] From /usr/local/lib/python3.6/dist-packages/tensorflow/python/framework/graph_util_impl.py:270: extract_sub_graph (from tensorflow.python.framework.graph_util_impl) is deprecated and will be removed in a future version.\n",
            "Instructions for updating:\n",
            "Use `tf.compat.v1.graph_util.extract_sub_graph`\n",
            "INFO:tensorflow:Froze 387 variables.\n",
            "I0513 14:31:22.311474 140206359324544 graph_util_impl.py:311] Froze 387 variables.\n",
            "INFO:tensorflow:Converted 387 variables to const ops.\n",
            "I0513 14:31:22.391483 140206359324544 graph_util_impl.py:364] Converted 387 variables to const ops.\n",
            "2020-05-13 14:31:22.489534: I tensorflow/tools/graph_transforms/transform_graph.cc:317] Applying strip_unused_nodes\n"
          ],
          "name": "stdout"
        }
      ]
    },
    {
      "cell_type": "markdown",
      "metadata": {
        "id": "FnzCz1NXsL_n",
        "colab_type": "text"
      },
      "source": [
        "# **toco TensorFlow Lite Optimized Converter**\n",
        "Generates bounding box correctly using TensorFLow Lite Interpreter in PC and app downloaded in phone using Android Studio"
      ]
    },
    {
      "cell_type": "code",
      "metadata": {
        "id": "JiVn6faQsIIk",
        "colab_type": "code",
        "outputId": "a70bb45d-b034-4b2e-d52e-54b5a71fc4ff",
        "colab": {
          "base_uri": "https://localhost:8080/",
          "height": 801
        }
      },
      "source": [
        "!toco \\\n",
        "--graph_def_file=\"/content/sample_data/tflite_graph.pb\" \\\n",
        "--output_file=\"/content/sample_data/burgerfries_toco_gcloud.tflite\" \\\n",
        "--input_shapes=1,300,300,3 \\\n",
        "--input_arrays=normalized_input_image_tensor \\\n",
        "--output_arrays='TFLite_Detection_PostProcess','TFLite_Detection_PostProcess:1','TFLite_Detection_PostProcess:2','TFLite_Detection_PostProcess:3'  \\\n",
        "--inference_type=QUANTIZED_UINT8 \\\n",
        "--mean_values=128 \\\n",
        "--std_dev_values=128 \\\n",
        "--change_concat_input_ranges=false \\\n",
        "--allow_custom_ops"
      ],
      "execution_count": 7,
      "outputs": [
        {
          "output_type": "stream",
          "text": [
            "2020-05-13 14:32:56.932589: I tensorflow/stream_executor/platform/default/dso_loader.cc:42] Successfully opened dynamic library libcuda.so.1\n",
            "2020-05-13 14:32:56.950540: I tensorflow/stream_executor/cuda/cuda_gpu_executor.cc:1005] successful NUMA node read from SysFS had negative value (-1), but there must be at least one NUMA node, so returning NUMA node zero\n",
            "2020-05-13 14:32:56.951349: I tensorflow/core/common_runtime/gpu/gpu_device.cc:1640] Found device 0 with properties: \n",
            "name: Tesla K80 major: 3 minor: 7 memoryClockRate(GHz): 0.8235\n",
            "pciBusID: 0000:00:04.0\n",
            "2020-05-13 14:32:56.951639: I tensorflow/stream_executor/platform/default/dso_loader.cc:42] Successfully opened dynamic library libcudart.so.10.0\n",
            "2020-05-13 14:32:56.953038: I tensorflow/stream_executor/platform/default/dso_loader.cc:42] Successfully opened dynamic library libcublas.so.10.0\n",
            "2020-05-13 14:32:56.954189: I tensorflow/stream_executor/platform/default/dso_loader.cc:42] Successfully opened dynamic library libcufft.so.10.0\n",
            "2020-05-13 14:32:56.954544: I tensorflow/stream_executor/platform/default/dso_loader.cc:42] Successfully opened dynamic library libcurand.so.10.0\n",
            "2020-05-13 14:32:56.956493: I tensorflow/stream_executor/platform/default/dso_loader.cc:42] Successfully opened dynamic library libcusolver.so.10.0\n",
            "2020-05-13 14:32:56.957748: I tensorflow/stream_executor/platform/default/dso_loader.cc:42] Successfully opened dynamic library libcusparse.so.10.0\n",
            "2020-05-13 14:32:56.962138: I tensorflow/stream_executor/platform/default/dso_loader.cc:42] Successfully opened dynamic library libcudnn.so.7\n",
            "2020-05-13 14:32:56.962281: I tensorflow/stream_executor/cuda/cuda_gpu_executor.cc:1005] successful NUMA node read from SysFS had negative value (-1), but there must be at least one NUMA node, so returning NUMA node zero\n",
            "2020-05-13 14:32:56.963103: I tensorflow/stream_executor/cuda/cuda_gpu_executor.cc:1005] successful NUMA node read from SysFS had negative value (-1), but there must be at least one NUMA node, so returning NUMA node zero\n",
            "2020-05-13 14:32:56.963863: I tensorflow/core/common_runtime/gpu/gpu_device.cc:1763] Adding visible gpu devices: 0\n",
            "2020-05-13 14:32:56.964297: I tensorflow/core/platform/cpu_feature_guard.cc:142] Your CPU supports instructions that this TensorFlow binary was not compiled to use: AVX2 FMA\n",
            "2020-05-13 14:32:57.026987: I tensorflow/stream_executor/cuda/cuda_gpu_executor.cc:1005] successful NUMA node read from SysFS had negative value (-1), but there must be at least one NUMA node, so returning NUMA node zero\n",
            "2020-05-13 14:32:57.027952: I tensorflow/compiler/xla/service/service.cc:168] XLA service 0x173fc00 executing computations on platform CUDA. Devices:\n",
            "2020-05-13 14:32:57.027988: I tensorflow/compiler/xla/service/service.cc:175]   StreamExecutor device (0): Tesla K80, Compute Capability 3.7\n",
            "2020-05-13 14:32:57.030148: I tensorflow/core/platform/profile_utils/cpu_utils.cc:94] CPU Frequency: 2300000000 Hz\n",
            "2020-05-13 14:32:57.030389: I tensorflow/compiler/xla/service/service.cc:168] XLA service 0x1740a00 executing computations on platform Host. Devices:\n",
            "2020-05-13 14:32:57.030434: I tensorflow/compiler/xla/service/service.cc:175]   StreamExecutor device (0): <undefined>, <undefined>\n",
            "2020-05-13 14:32:57.030658: I tensorflow/stream_executor/cuda/cuda_gpu_executor.cc:1005] successful NUMA node read from SysFS had negative value (-1), but there must be at least one NUMA node, so returning NUMA node zero\n",
            "2020-05-13 14:32:57.031382: I tensorflow/core/common_runtime/gpu/gpu_device.cc:1640] Found device 0 with properties: \n",
            "name: Tesla K80 major: 3 minor: 7 memoryClockRate(GHz): 0.8235\n",
            "pciBusID: 0000:00:04.0\n",
            "2020-05-13 14:32:57.031452: I tensorflow/stream_executor/platform/default/dso_loader.cc:42] Successfully opened dynamic library libcudart.so.10.0\n",
            "2020-05-13 14:32:57.031499: I tensorflow/stream_executor/platform/default/dso_loader.cc:42] Successfully opened dynamic library libcublas.so.10.0\n",
            "2020-05-13 14:32:57.031564: I tensorflow/stream_executor/platform/default/dso_loader.cc:42] Successfully opened dynamic library libcufft.so.10.0\n",
            "2020-05-13 14:32:57.031610: I tensorflow/stream_executor/platform/default/dso_loader.cc:42] Successfully opened dynamic library libcurand.so.10.0\n",
            "2020-05-13 14:32:57.031650: I tensorflow/stream_executor/platform/default/dso_loader.cc:42] Successfully opened dynamic library libcusolver.so.10.0\n",
            "2020-05-13 14:32:57.031685: I tensorflow/stream_executor/platform/default/dso_loader.cc:42] Successfully opened dynamic library libcusparse.so.10.0\n",
            "2020-05-13 14:32:57.031721: I tensorflow/stream_executor/platform/default/dso_loader.cc:42] Successfully opened dynamic library libcudnn.so.7\n",
            "2020-05-13 14:32:57.031860: I tensorflow/stream_executor/cuda/cuda_gpu_executor.cc:1005] successful NUMA node read from SysFS had negative value (-1), but there must be at least one NUMA node, so returning NUMA node zero\n",
            "2020-05-13 14:32:57.032613: I tensorflow/stream_executor/cuda/cuda_gpu_executor.cc:1005] successful NUMA node read from SysFS had negative value (-1), but there must be at least one NUMA node, so returning NUMA node zero\n",
            "2020-05-13 14:32:57.033320: I tensorflow/core/common_runtime/gpu/gpu_device.cc:1763] Adding visible gpu devices: 0\n",
            "2020-05-13 14:32:57.033386: I tensorflow/stream_executor/platform/default/dso_loader.cc:42] Successfully opened dynamic library libcudart.so.10.0\n",
            "2020-05-13 14:32:57.034749: I tensorflow/core/common_runtime/gpu/gpu_device.cc:1181] Device interconnect StreamExecutor with strength 1 edge matrix:\n",
            "2020-05-13 14:32:57.034792: I tensorflow/core/common_runtime/gpu/gpu_device.cc:1187]      0 \n",
            "2020-05-13 14:32:57.034811: I tensorflow/core/common_runtime/gpu/gpu_device.cc:1200] 0:   N \n",
            "2020-05-13 14:32:57.034997: I tensorflow/stream_executor/cuda/cuda_gpu_executor.cc:1005] successful NUMA node read from SysFS had negative value (-1), but there must be at least one NUMA node, so returning NUMA node zero\n",
            "2020-05-13 14:32:57.035746: I tensorflow/stream_executor/cuda/cuda_gpu_executor.cc:1005] successful NUMA node read from SysFS had negative value (-1), but there must be at least one NUMA node, so returning NUMA node zero\n",
            "2020-05-13 14:32:57.036472: W tensorflow/core/common_runtime/gpu/gpu_bfc_allocator.cc:40] Overriding allow_growth setting because the TF_FORCE_GPU_ALLOW_GROWTH environment variable is set. Original config value was 0.\n",
            "2020-05-13 14:32:57.036523: I tensorflow/core/common_runtime/gpu/gpu_device.cc:1326] Created TensorFlow device (/job:localhost/replica:0/task:0/device:GPU:0 with 10805 MB memory) -> physical GPU (device: 0, name: Tesla K80, pci bus id: 0000:00:04.0, compute capability: 3.7)\n"
          ],
          "name": "stdout"
        }
      ]
    }
  ]
}